Workbook
Name ABJ: 10^9
Name ABW: " अब्ज "
Name Demand: 'न.८ साठीचे दर'!$A$10:$C$18
Name GPA: 'नमुना ८'!$T$11:$T$639
Name HZR: 10^3
Name HZW: " हजार "
Name KTI: 10^7
Name KTW: " कोटी "
Name LKS: 10^5
Name LKW: " लक्ष "
Name LMT: अकरा अंकी संख्यापर्यंत फक्त
Name Name: 'नमुना ८'!$E$11:$E$639
Name Namuna8: 'नमुना ८'!$A$10:$AD$666
Name NamunaNo8: 'नमुना ८'!$A$9:$AD$666
Name Rate: 'न.८ साठीचे दर'!$A$3:$B$7
Name RateB: 'न.८ साठीचे दर'!$A$3:$E$7
Name SHE: "शे "
Name SNT: 'नमुना ८'!$U$11:$U$639
Name STK: "शंभर"
Name WST: 'नमुना ८'!$W$11:$W$639
Name ZRO: "शून्य"

Sheet मुख्य पान 
E2: बळसाणे | I2: साक्री | M2: धुळे

Sheet अंदाजपत्रक 
A2: जमा | H2: खर्च
A3: जमा लेखा शिर्ष | D3: २०२०/२०२१या वर्षासाठी पंचायतीची अंदाजित प्राप्ती | E3: २०१९/२०२० चालु वर्षासाठी मंजूर केलेली अंदाजित प्राप्ती | F3: २०१८/ २०१९ मागील वर्षी मिळालेली प्रत्यक्ष रक्कम | G3: २०१७/ २०१८गतपूर्व वर्षात वर्षात मिळालेली प्रत्यक्ष रक्कम | H3: खर्च लेखा शिर्ष | K3: २०२०/२०२१ या वर्षासाठी पंचायतीची अंदाजित खर्च | L3: २०१९/२०२० चालु वर्षासाठी मंजूर केलेली खर्चाची अंदाजित रक्कम | M3: २०१८/२०१९ मागील वर्षी मिळालेली प्रत्यक्ष खर्च | N3: २०१७/२०१८ गत पूर्व वर्षी मिळालेली प्रत्यक्ष खर्च
B4: 1 | D4: 2 | E4: 3 | F4: 4 | G4: 5 | I4: 6 | K4: 7 | L4: 8 | M4: 9 | N4: 10
A5: ( एक ) | B5: ग्रामनिधी जमा | H5: ( एक ) | I5: ग्रामनिधीतून खर्च
A6: ( एक ) | B6: ( अ ) कर | H6: 1 | I6: सरपंच मानधन | J6: २५१५-१०३-०५
A7: 1 | B7: मालमत्ता कर, जमिनी व इमारती यावरील कर | H7: 2 | I7: सदस्य बैठक भत्ता | J7: १६०१-१०२-२०५३-१०४२-३१
B8: निवासी इमारतीवरील कर | C8: ००३५-१०१ | H8: 3 | I8: सदस्य / सरपंच प्रवास भत्ता | J8: २५१५-१०३-११
B9: अनिवासी इमारती, खुल्या ( अकृषक ) जागेवरील कर | C9: ००३५-१०२ | H9: 4 | I9: कर्मचारी वेतन | J9: २५१५-१०३-०१
A10: 2 | B10: दिवाबत्ती | C10: ००४४-१०१ | H10: 5 | I10: कर्मचारी प्रवास भत्ता | J10: २५१५-१०३-A११
A11: 3 | B11: स्वच्छता कर | C11: ०२१५-१०३ | H11: 6 | I11: कार्यालयीन खर्च | J11: २५१५-१०३-१३
A12: 4 | B12: दुकाने, लघु उद्योग व हॉटेल चालविणे यावरील कर | C12: ००२८-१०२ | H12: 7 | I12: दुरुस्ती व देखभाल | J12: २०५९-१०१-२७
A13: 5 | B13: यात्रा कर | C13: ००४२-१०३ | H13: 8 | I13: स्वच्छता | J13: 2215
A14: 6 | B14: जत्रा, उत्सव व इतर मनोरंजन कर | H14: 9 | I14: पाणी पुरवठा
B15: जत्रा व उत्सव कर | C15: ०२०६-१०२ | I15: पाईप लाईन दुरुस्ती | J15: २२१५-१०१-०२
B16: मनरंजन कर | C16: ००४५-१०१ | I16: पाणी पुरवठा नवीन कामे | J16: ४२१५-१०२-५३
A17: 7 | B17: सायकल व इतर वाहनावरील कर | C17: ००४१-८०० | I17: पाणी पुरवठा कर्मचारी वेतन | J17: २२१५-१०३-०१
A18: 8 | B18: टोल tax | C18: ००४२-९०१ | I18: पाणी मीटर / साहित्य खरेदी | J18: २२१५-१०१-२१
A19: 9 | B19: उतारू व मालावरील कर | C19: ००४२-१०२ | I19: नळमार्गाचे परीक्षण व दुरुस्ती | J19: २२१५-१०१-२७
A20: 10 | B20: वनविकास कर | C20: ०४०६-४२ | I20: शासकीय पाणीपट्टीचा भरणा करणे | J20: २२१५-१०१-१४
A21: 11 | B21: सेवा कर | C21: ००४४-९०१ | I21: नलिका विहिरीची देखभाल व दुरुस्ती | J21: २२१५-१०२-२७
A22: 12 | B22: व्यापारी किंवा अजीविका यावरील कर ( शेतीव्यतिरिक्त ) | C22: ००२८-१०२ | I22: हात पंप / वीज पंप वर्गणी | J22: २२१५-१०२-३२
A23: 13 | B23: गुरांच्या बाजारावरील दलालीचा व्यवसाय व अजीविकेवरील कर | C23: ००४५-८०० | I23: निर्मल भारत अभियान | J23: २२१५-१०३-५०
A24: 14 | B24: इतर ( वर्गणी ) | H24: 10 | I24: वीज देयक
I25: ( अ ) पाणी पुरवठा | J25: २२१५-१०१-१३
I26: ( ब ) रस्त्यावरील दिवाबत्ती | J26: १६०१-१०२-३६०४-०३२५-५०
I27: ( क ) कार्यालय | J27: २८०१-१०१-२१
H28: 11 | I28: पथ दिवाबत्ती, साहित्य व इतर | J28: २८०१-१०३-२१
B29: एकूण ( एक ) ( अ ) कर | D29: =SUM(D7:D28) -> 0 | E29: =SUM(E7:E28) -> 0 | F29: =SUM(F7:F28) -> 0 | G29: =SUM(G7:G28) -> 0 | I29: दिवाबत्ती मजुरी | J29: २८०१-१०३-०२
A30: ( एक ) | B30: ( ब ) करेत्तर उत्पन्न | H30: 12 | I30: शिक्षण | J30: 22024202
A31: 1 | B31: बाजार फी | C31: ०२०६-१०१ | H31: 13 | I31: आरोग्य | J31: 22104210
A32: 2 | B32: टांगा थांबा फी | C32: ००४५-८०० | H32: 14 | I32: रस्ते व गटार
A33: 3 | B33: कार थांबा फी | C33: ००४५-८०० | I33: रस्ते देखभाल दुरुस्ती | J33: ३०५४-१०१-२७
A34: 4 | B34: पाणी पट्टी | I34: रस्ते नवीन | J34: ५०५४-१०१-५३
B35: जनरल पाणीपट्टी | C35: ०२१५-८०० | I35: गटार देखभाल दुरुस्ती | J35: २०५९-१०१-२७
B36: स्पेशल पाणीपट्टी | C36: ०२१५-१०१ | I36: गटार नवीन | J36: ५०५४-१०२-५३
A37: 5 | B37: स्वच्छता फी | C37: ०२१५-१०३ | H37: 15 | I37: अन्य बांधकाम
A38: 6 | B38: गाय चरण फी | C38: ०४०३-१०४ | I38: मुतारी दुरुस्ती
A39: 7 | B39: डीव्हीडीएफ व्याज २.५ % | C39: ००४९-८०० | I39: स्मशानभूमी दुरुस्ती
A40: 8 | B40: जमीन भाडेपट्टी | C40: ०५१५-४२
A41: 9 | B41: व्याज जमा | C41: ००४९-१०१
...

Sheet वार्षिक अहवाल 
A2: विभागातील ग्रा.पं. कारभारावर आधारित सन | H2: २०२०/२१ | J2: वार्षिक प्रशासन अहवाल
A3: प्रकरण 15
A4: विवरण पत्र - अ
A5: अ.क्र. | B5: पंचायत समितीचे नांव | C5: एकूण ग्राम पंचायतींची संख्या | D5: सन 2011 ची खाने सुमारी | E5: सर्व साधारण जागा | F5: ग्रामपंचायतीच्या राखुन ठेवलेल्या जागा | J5: सहकारी सदस्यांची संख्या | K5: एकूण सदस्य ५+९+१० | L5: निवडणूक झालेल्या एकूण ग्रा.पं. संख्या | M5: पोट निवडणूक झालेल्या ग्रामपंचायती | N5: नेमलेल्या किंवा निवडून सर्वसाधारण | P5: एकूण सभासद (१४+१५)
F6: स्त्रिया | G6: अनुसूचित जाती | H6: अनुसूचित जमाती | I6: एकूण राखीव जागा (६+७+८) | N6: सभासदांची संख्या निवडून आलेले सभासद | O6: राखीव नसलेल्या जिल्हा परिषदेच्या जागा स्थायी समितीने नेमलेले
A7: 1 | B7: 2 | C7: 3 | D7: 4 | E7: 5 | F7: 6 | G7: 7 | H7: 8 | I7: 9 | J7: 10 | K7: 11 | L7: 12 | M7: 13 | N7: 14 | O7: 15 | P7: 16
A8: 1 | B8: ='मुख्य पान '!I2 -> साक्री | C8: 1 | E8: 2 | F8: 4 | G8: 1 | H8: 2 | I8: =SUM(F8:H8) -> 7 | J8: 0 | K8: =SUM(E8+I8+J8) -> 9 | O8: 0 | P8: =N8+O8 -> 0
A10: अ.क्र. | B10: पंचायत समितीचे नांव | C10: एकूण ग्राम पंचायतींची संख्या | D10: स्त्रिया निवडून आलेले सभासद | E10: राखीव जागा जिल्हा परिषद स्थायी समितीने नेमलेले सभासद | F10: एकूण सभासद (१७+१८) | G10: राखीव अनुसूचित जाती | J10: अनुसूचित जमाती | M10: एकूण निवडून आलेले सभासद | N10: एकूण नेमलेले | O10: एकूण सहयोगी सभासद | P10: निवडून आलेले व नेमलेले सहयोगी सभासदांची संख्या (२६+२७+२८)
G11: सभासदांची संख्या अनुसूचित जाती निवडून आलेले सभासद | H11: जिल्हा परिषद स्थायी समितीने नेमलेले | I11: एकूण सभासद संख्या | J11: निवडून आलेले सभासद | K11: जिल्हा परिषद स्थायी समितीने नेमलेले | L11: एकूण सभासद (२३+२४)
A12: 1 | B12: 2 | C12: 3 | D12: 17 | E12: 18 | F12: 19 | G12: 20 | H12: 21 | I12: 22 | J12: 23 | K12: 24 | L12: 25 | M12: 26 | N12: 27 | O12: 28 | P12: 29
A13: =A8 -> 1 | B13: =B8 -> साक्री | F13: =SUM(D13:E13) -> 0 | I13: =SUM(G13:H13) -> 0 | K13: 0 | L13: =SUM(J13:K13) -> 0 | M13: =SUM(P8+F13+I13+L13) -> 0 | P13: =SUM(M13+N13+O13) -> 0
A15: विवरण क व ड
A16: सन 2019-2020 ग्राम पंचायतींना सरकारकडून मिळालेले अनुदाने
A17: अ.क्र | B17: पंचायत समितीचे नांव | C17: एकूण ग्रामपंचायत संख्या | D17: जमीन महसूल अनुदान | E17: समानीकरण अनुदान | F17: ग्राम पंचायत कायदा कलम १२७ प्रमाणे स्थानिक उपकर | G17: विकास कामासाठी अनुदान | H17: एकूण ४ ते 5 ची बेरीज | I17: अंशदान ( सरपंच मानधन, सदस्य बैठक भत्ता कर्मचारी वेतन ) इ | J17: देणग्‍या | K17: बक्षिस | L17: नियमाचा भंग केल्याबद्दल | M17: इतर निर्दिष्ट न केलेल्या बाबी | N17: देणगी अनुदान वर्गणीची बेरीज ९ ते १३ | O17: इमारतीवरील व जमिनीवरील कर | P17: दिवाबत्ती कर | Q17: जत्रा कर | T17: बाजार फी
A18: 1 | B18: 2 | C18: 3 | D18: 4 | E18: 5 | F18: 6 | G18: 7 | H18: 8 | I18: 9 | J18: 10 | K18: 11 | L18: 12 | M18: 13 | N18: 14 | O18: 15 | P18: 15अ | Q18: 16 | T18: टांगा थांबा फी
A19: =A13 -> 1 | B19: =B13 -> साक्री | D19: ='N No. 3-4 '!D57 -> 0 | E19: ='N No. 3-4 '!D58 -> 0 | F19: ='N No. 3-4 '!D55+'N No. 3-4 '!D56+'N No. 3-4 '!D59+'N No. 3-4 '!D63 -> 0 | G19: ='N No. 3-4 '!D72+'N No. 3-4 '!D73+'N No. 3-4 '!D75+'N No. 3-4 '!D76+'N No. 3-4 '!#REF!+'N No. 3-4 '!D84+'N No. 3-4 '!D85+'N No. 3-4 '!D86+'N No. 3-4 '!D87+'N No. 3-4 '!D84+'N No. 3-4 '!D85 -> #REF! | H19: =SUM(D19:G19) -> #REF! | I19: ='N No. 3-4 '!D65+'N No. 3-4 '!D66+'N No. 3-4 '!D67 -> 0 | J19: ='N No. 3-4 '!D60+'N No. 3-4 '!D62+'N No. 3-4 '!D44 -> 0 | K19: ='N No. 3-4 '!D88 -> 69 | M19: ='N No. 3-4 '!D77+'N No. 3-4 '!D78+'N No. 3-4 '!D74 -> 60 | N19: =SUM(I19:M19) -> 129 | O19: ='N No. 3-4 '!D8+'N No. 3-4 '!D9 -> 0 | P19: ='N No. 3-4 '!D10 -> 0 | Q19: ='N No. 3-4 '!D13 -> 0 | R19: =SUM(O19:Q19) -> 0 | T19: कार थांबा फी
T20: पाणी पट्टी
A21: चुंगी कर | B21: दुकानावरील हॉटेलवरील कर | C21: सायकल व वाहने इत्यादीवरील कर | D21: शेतीखेरीज बाष्प, तेल, विद्युतशक्तीच्या सहाय्याने केला जाणारा धंदा किंवा व्यवसायावरील कर | E21: गुरांच्या बाजारातील दलालीच्या धंदयावरील कर | F21: यात्रा, उत्सव यांचे करमणुकी वरील कर | G21: बाजार व आठवडा बाजारावरील कर | H21: कोणतीही सार्वजनिक जागा किंवा ठिकाणे या वरील तात्पुरते इमले उभारणे व किंवा कोणतेही भाग पुढे आणणे किंवा त्याचा भोगवटा करणे यावरील कर | I21: बैलगाडयांच्या अडयावरील कर | J21: कारखान्यां कडून मिळालेली ठोक वर्गणी | K21: विहीर व तळी पासून पाण्याचा पुरवठा करण्याबाबत कर | L21: सर्वसाधारण विशेष साफ सफाई पट्टी | M21: वाहने व जनावरे या वरील जकात | N21: गुरे चरण्याबद्दल फी | O21: इतर कर फी | P21: एकूण बेरीज १५ ते ३२ | T21: जनरल पाणीपट्टी
A22: 17 | B22: 18 | C22: 19 | D22: 20 | E22: 21 | F22: 22 | G22: 23 | H22: 24 | I22: 25 | J22: 26 | K22: 27 | L22: 28 | M22: 29 | N22: 30 | O22: 31 | P22: 32 | T22: स्पेशल पाणीपट्टी
A23: ='N No. 3-4 '!D18 -> 0 | B23: ='N No. 3-4 '!D12 -> 0 | C23: ='N No. 3-4 '!D17 -> 0 | D23: ='N No. 3-4 '!D22 -> 0 | E23: ='N No. 3-4 '!D23 -> 0 | F23: ='N No. 3-4 '!D15+'N No. 3-4 '!D16 -> 0 | G23: ='N No. 3-4 '!D31 -> 0 | H23: ='N No. 3-4 '!D40+'N No. 3-4 '!D42+'N No. 3-4 '!D43+'N No. 3-4 '!D47 -> 0 | I23: ='N No. 3-4 '!D19 -> 0 | J23: ='N No. 3-4 '!D64 -> 0 | L23: ='N No. 3-4 '!D37+'N No. 3-4 '!D11 -> 0 | M23: ='N No. 3-4 '!D32+'N No. 3-4 '!D33 -> 0 | N23: ='N No. 3-4 '!D38 -> 0 | O23: ='N No. 3-4 '!D20+'N No. 3-4 '!D21+'N No. 3-4 '!D39+'N No. 3-4 '!D41+'N No. 3-4 '!D48+'N No. 3-4 '!D100+'N No. 3-4 '!D101+'N No. 3-4 '!D106+'N No. 3-4 '!D24+'N No. 3-4 '!D46+'N No. 3-4 '!D103+'N No. 3-4 '!D104+'N No. 3-4 '!D105 -> 505 | P23: =R19+R23 -> 505 | R23: =SUM(A23:O23) -> 505 | T23: स्वच्छता फी
T24: गाय चरण फी
T25: जागा भाडे
A26: पा. पु. निधीकडे जि. प. ग्रामीण पा. पु. निधीतील रकमेपोटी मिळालेले अनुदान | C26: पं. स./ जि. प. सेस फंडातील मिळालेले अनुदान | D26: वीज बिलाचे ५०% अनुदान जमा | E26: सर्वसाधारण पाणी पट्टी | F26: विशेष पाणी पट्टी | G26: एकूण | H26: वर्षात नळ धारकाकडून अनामत व नल जोडणी फी. | I26: पाणी पुरवठा साधनापोटी अन्य मार्गाने जमा | J26: जमीन महसूल अनुदानाच्या ३५ % जमा | K26: एकूण जमा | L26: एकूण मिळालेल्या उत्पन्नाची बेरीज ८+१४+३३ | M26: दर माणसी कराचा तक्‍ता | N26: दर माणसी कराचा बोजा | O26: मागील वर्षातील एकूण उत्पन्न | P26: मागील वर्षातील प्रमाण वाढ व घट | Q26: वाढ व घट झाल्याची कारणे | T26: कोंडवाडा जमा
A27: 33 | C27: 34 | D27: 35 | E27: 36 | F27: 37 | G27: 38 | H27: 39 | I27: 40 | J27: 41 | K27: 42 | L27: 43 | M27: 44 | N27: 45 | O27: 46 | P27: 47 | Q27: 48 | T27: ='N No. 3-4 '!D145 -> 124
A28: ='N No. 3-4 '!D79 -> 61 | D28: ='N No. 3-4 '!D61 -> 0 | E28: ='N No. 3-4 '!D35 -> 0 | F28: ='N No. 3-4 '!D36 -> 0 | G28: =E28+F28 -> 0 | H28: ='N No. 3-4 '!D49 -> 0 | I28: ='N No. 3-4 '!D50+'N No. 3-4 '!D107 -> 88 | K28: =J28+I28+H28+G28+D28+C28+A28 -> 149 | L28: =H19+N19+P23+K28 -> #REF! | T28: =T27-L28 -> #REF!
T29: लिलाव ( धूळ, घाण, शेण, केरकचरा, जनावरांची प्रेत व इतर)
A30: विवरणपत्र इ - सन | J30: =H2 -> २०२०/२१ | T30: इमारत भाडे
A31: अ.क्र | B31: ग्रामपंचायतीचे नांव | C31: एकूण ग्रामपंचायतींची संख्या | D31: स्वच्छता आरोग्य यावरील खर्च | F31: दफणभुमी व दहनभुमी याची व्यवस्था | G31: क्रिडांगणे व सार्वजनिक उद्याने | H31: बेवारशी प्रेते व गुरे ढोरे यांची विल्हेवाट लावणे | I31: सार्वजनिक व वैयक्तिक शौचालय | J31: साथीचे रोग आणि गुरांचे संगोपन | K31: प्रसुती व महिला बालकल्याण | L31: वैद्यकीय मदत | M31: माणसांना व गुरांना लस टोचने | N31: स्वच्छता विषयक व आरोग्य विषयक उपाययोजना | O31: स्तंभ ४ ते १३ यांची बेरीज | P31: अतिक्रमणे | T31: दाखले फी
D32: पाणी पुरवठा | E32: सार्वजनिक रस्ते गटारे विहीरी साफ करणे व उपद्गव कमी करणे | T32: पाणी पुरवठा वर्गणी
A33: 1 | B33: 2 | C33: 3 | D33: 4 | E33: 5 | F33: 6 | G33: 7 | H33: 8 | I33: 9 | J33: 10 | K33: १०अ | L33: 11 | M33: 12 | N33: 13 | O33: 14 | P33: 15 | T33: पाणी पुरवठा दुरुस्ती निधी
B34: ='मुख्य पान '!E2 -> बळसाणे | E34: ='N No. 3-4 '!#REF! -> #REF! | F34: ='N No. 3-4 '!H39 -> 2 | I34: ='N No. 3-4 '!H72 -> 0 | L34: ='N No. 3-4 '!H61 -> 0 | N34: ='N No. 3-4 '!H31+'N No. 3-4 '!H13 -> 4 | O34: =SUM(D34:N34) -> #REF! | T34: जागा भाडे
T35: कोंडवाडा जमा
A36: अ.क्र | B36: ग्रामपंचायतीचे नांव | C36: एकूण ग्रामपंचायतींची संख्या | D36: रस्ते बांधणी, गटार बांधणी व ती व्यवस्थित ठेवणे व दुरुस्त करणे | E36: सार्वजनिक इमारती व विहीरी | F36: रस्त्यावरील दिवाबत्ती | G36: जत्रा बाजार व बैलगाडी अड्डा | H36: कत्‍तल खाना | I36: झाडे लावणे व निगा राखणे | J36: धर्मशाळा | K36: स्नान करणेसाठी व कपडे धुण्यासाठी बांधलेले घाट | L36: बाजार/शौचालय अनुदान | M36: साफसफाई नोकर वर्गासाठी | N36: शिबीरासाठी उपयोगी पडणारे मैदान करणे व खळी | O36: गुरांचे कोंडवाडे | P36: दुष्काळी कामे | T36: देणगी
T37: इतर जमा
A38: 1 | B38: 2 | C38: 3 | D38: 16 | E38: 17 | F38: 18 | G38: 19 | H38: 20 | I38: 21 | J38: 22 | K38: 23 | L38: 24 | M38: 25 | N38: 26 | O38: 27 | P38: 28 | T38: लिलाव ( धूळ, घाण, शेण, केरकचरा, जनावरांची प्रेत व इतर)
B39: =B34 -> बळसाणे | D39: ='N No. 3-4 '!H33+'N No. 3-4 '!H34+'N No. 3-4 '!H35+'N No. 3-4 '!H36 -> 8 | E39: ='N No. 3-4 '!H38 -> 2 | F39: ='N No. 3-4 '!H26+'N No. 3-4 '!H28+'N No. 3-4 '!H29 -> 6 | O39: ='N No. 3-4 '!H51 -> 0 | T39: इमारत भाडे
T40: दाखले फी
A41: अ.क्र | B41: ग्रामपंचायतीचे नांव | C41: एकूण ग्रामपंचायतींची संख्या | D41: गावठणाच्या क्षेत्राचा विस्तार | E41: वखारी | F41: सार्वजनिक बांधकामाच्या इतर कोणत्याही बाबी विकास काम | G41: स्तंभ १५ ते ३१ ची बेरीज | H41: शिक्षण व सांस्कृतिक कार्य यावरील खर्च | K41: ग्रंथालय विषयक वाचनालय | L41: सामाजिक व नैतिक कल्याण प्रगती वरील खर्च | Q41: स्तंभ ३३ ते ४१ ची बेरीज | T41: पाणी पुरवठा वर्गणी
H42: शिक्षण | I42: आखाडे व क्लब करमणूक | J42: कला व संस्कृति विकासा करीता नाटयगृह | L42: दारुबंदी | M42: अस्पुश्यता निवारण वइतर कामे | N42: मागासवर्गीय स्थिती सुधारणा | O42: १०टक्‍के म.बा.क. खर्च | P42: इतर कोणतीही बाब | T42: पाणी पुरवठा दुरुस्ती निधी
A43: 1 | B43: 2 | C43: 3 | D43: 29 | E43: 30 | F43: 31 | G43: 32 | H43: 33 | I43: 34 | J43: 35 | K43: 36 | L43: 37 | M43: 38 | N43: 39 | O43: 40 | P43: 41 | Q43: 42
...

Sheet N No. 3-4 
A2: जमा | E2: खर्च
A3: जमा लेखा शिर्ष | D3: रक्कम | E3: खर्च लेखा शिर्ष | H3: रक्कम | I3: रक्कम
B4: 1 | D4: 2 | F4: 3 | H4: 4 | I4: 4
A5: ( एक ) | B5: ग्रामनिधी जमा | E5: ( एक ) | F5: ग्रामनिधीतून खर्च
A6: ( एक ) | B6: ( अ ) कर | E6: 1 | F6: सरपंच मानधन | G6: २५१५-१०३-०५ | H6: ='ग्रामनिधी ३-४ '!BW5 -> 2 | I6: ='ग्रामनिधी ३-४ '!BX5 -> 0
A7: 1 | B7: मालमत्ता कर, जमिनी व इमारती यावरील कर | E7: 2 | F7: सदस्य बैठक भत्ता | G7: १६०१-१०२-२०५३-१०४२-३१ | H7: ='ग्रामनिधी ३-४ '!BW6 -> 2 | I7: ='ग्रामनिधी ३-४ '!BX6 -> 0
B8: निवासी इमारतीवरील कर | C8: ००३५-१०१ | D8: ='ग्रामनिधी ३-४ '!AL5 -> 0 | E8: 3 | F8: सदस्य / सरपंच प्रवास भत्ता | G8: २५१५-१०३-११ | H8: ='ग्रामनिधी ३-४ '!BW7 -> 2 | I8: ='ग्रामनिधी ३-४ '!BX7+'पाणीपट्टी ३-४'!BX6 -> 0
B9: अनिवासी इमारती, खुल्या ( अकृषक ) जागेवरील कर | C9: ००३५-१०२ | D9: ='ग्रामनिधी ३-४ '!AL6 -> 0 | E9: 4 | F9: कर्मचारी वेतन | G9: २५१५-१०३-०१ | H9: ='ग्रामनिधी ३-४ '!BW8 -> 2 | I9: ='ग्रामनिधी ३-४ '!BX8+'पाणीपट्टी ३-४'!BX5 -> 0
A10: 2 | B10: दिवाबत्ती | C10: ००४४-१०१ | D10: ='ग्रामनिधी ३-४ '!AL7 -> 0 | E10: 5 | F10: कर्मचारी प्रवास भत्ता | G10: २५१५-१०३-A११ | H10: ='ग्रामनिधी ३-४ '!BW10+'पाणीपट्टी ३-४'!BW6 -> 2 | I10: ='ग्रामनिधी ३-४ '!BX9 -> 0
A11: 3 | B11: स्वच्छता कर | C11: ०२१५-१०३ | D11: ='ग्रामनिधी ३-४ '!AL8 -> 0 | E11: 6 | F11: कार्यालयीन खर्च | G11: २५१५-१०३-१३ | H11: ='ग्रामनिधी ३-४ '!BW10 -> 2 | I11: ='ग्रामनिधी ३-४ '!BX10 -> 0
A12: 4 | B12: दुकाने, लघु उद्योग व हॉटेल चालविणे यावरील कर | C12: ००२८-१०२ | D12: ='ग्रामनिधी ३-४ '!AL9 -> 0 | E12: 7 | F12: दुरुस्ती व देखभाल | G12: २०५९-१०१-२७ | H12: ='ग्रामनिधी ३-४ '!BW11 -> 2 | I12: ='ग्रामनिधी ३-४ '!BX11+'पाणीपट्टी ३-४'!BX7 -> 0
A13: 5 | B13: यात्रा कर | C13: ००४२-१०३ | D13: ='ग्रामनिधी ३-४ '!AL10 -> 0 | E13: 8 | F13: स्वच्छता | G13: 2215 | H13: ='ग्रामनिधी ३-४ '!BW12+'पाणीपट्टी ३-४'!BW8 -> 2 | I13: ='ग्रामनिधी ३-४ '!BX12+'पाणीपट्टी ३-४'!BX8 -> 0
A14: 6 | B14: जत्रा, उत्सव व इतर मनोरंजन कर | E14: 9 | F14: पाणी पुरवठा
B15: जत्रा व उत्सव कर | C15: ०२०६-१०२ | D15: ='ग्रामनिधी ३-४ '!AL11 -> 0 | F15: पाईप लाईन दुरुस्ती | G15: २२१५-१०१-०२ | H15: ='पाणीपट्टी ३-४'!BW9 -> 0 | I15: ='पाणीपट्टी ३-४'!BX9 -> 0
B16: मनरंजन कर | C16: ००४५-१०१ | D16: 0 | F16: पाणी पुरवठा नवीन कामे | G16: ४२१५-१०२-५३ | H16: ='पाणीपट्टी ३-४'!BW10 -> 0 | I16: ='पाणीपट्टी ३-४'!BX10 -> 0
A17: 7 | B17: सायकल व इतर वाहनावरील कर | C17: ००४१-८०० | D17: 0 | F17: पाणी पुरवठा कर्मचारी वेतन | G17: २२१५-१०३-०१ | H17: ='पाणीपट्टी ३-४'!BW5+'पाणीपट्टी ३-४'!BW11 -> 1000 | I17: ='पाणीपट्टी ३-४'!BX11 -> 0
A18: 8 | B18: टोल tax | C18: ००४२-९०१ | D18: 0 | F18: पाणी मीटर / साहित्य खरेदी | G18: २२१५-१०१-२१ | H18: ='पाणीपट्टी ३-४'!BW12+'पाणीपट्टी ३-४'!BW19 -> 0 | I18: ='पाणीपट्टी ३-४'!BX12 -> 0
A19: 9 | B19: उतारू व मालावरील कर | C19: ००४२-१०२ | D19: 0 | F19: नळमार्गाचे परीक्षण व दुरुस्ती | G19: २२१५-१०१-२७ | H19: ='पाणीपट्टी ३-४'!BW13 -> 0 | I19: ='पाणीपट्टी ३-४'!BX13 -> 0
A20: 10 | B20: वनविकास कर | C20: ०४०६-४२ | D20: 0 | F20: शासकीय पाणीपट्टीचा भरणा करणे | G20: २२१५-१०१-१४ | H20: ='पाणीपट्टी ३-४'!BW14 -> 0 | I20: ='पाणीपट्टी ३-४'!BX14 -> 0
A21: 11 | B21: सेवा कर | C21: ००४४-९०१ | D21: 0 | F21: नलिका विहिरीची देखभाल व दुरुस्ती | G21: २२१५-१०२-२७ | H21: ='पाणीपट्टी ३-४'!BW15 -> 0 | I21: ='पाणीपट्टी ३-४'!BX15 -> 0
A22: 12 | B22: व्यापारी किंवा अजीविका यावरील कर ( शेतीव्यतिरिक्त ) | C22: ००२८-१०२ | D22: 0 | F22: हात पंप / वीज पंप वर्गणी | G22: २२१५-१०२-३२ | H22: ='पाणीपट्टी ३-४'!BW16 -> 0 | I22: ='पाणीपट्टी ३-४'!BX16 -> 0
A23: 13 | B23: गुरांच्या बाजारावरील दलालीचा व्यवसाय व अजीविकेवरील कर | C23: ००४५-८०० | D23: 0
A24: 14 | B24: इतर ( वर्गणी ) | D24: ='ग्रामनिधी ३-४ '!AL12 -> 0 | E24: 10 | F24: वीज देयक
F25: ( अ ) पाणी पुरवठा | G25: २२१५-१०१-१३ | H25: ='पाणीपट्टी ३-४'!BW17 -> 0 | I25: ='पाणीपट्टी ३-४'!BX17 -> 0
F26: ( ब ) रस्त्यावरील दिवाबत्ती | G26: १६०१-१०२-३६०४-०३२५-५० | H26: ='ग्रामनिधी ३-४ '!BW13 -> 2 | I26: ='ग्रामनिधी ३-४ '!BX13 -> 0
F27: ( क ) कार्यालय | G27: २८०१-१०१-२१ | H27: ='ग्रामनिधी ३-४ '!BW14 -> 2 | I27: ='ग्रामनिधी ३-४ '!BX14 -> 0
E28: 11 | F28: पथ दिवाबत्ती, साहित्य व इतर | G28: २८०१-१०३-२१ | H28: ='ग्रामनिधी ३-४ '!BW15 -> 2 | I28: ='ग्रामनिधी ३-४ '!BX15 -> 0
B29: एकूण ( एक ) ( अ ) कर | D29: =SUM(D8:D28) -> 0 | F29: दिवाबत्ती मजुरी | G29: २८०१-१०३-०२ | H29: ='ग्रामनिधी ३-४ '!BW16 -> 2 | I29: ='ग्रामनिधी ३-४ '!BX16 -> 0
A30: ( एक ) | B30: ( ब ) करेत्तर उत्पन्न | E30: 12 | F30: शिक्षण | G30: 22024202 | H30: ='ग्रामनिधी ३-४ '!BW17 -> 2 | I30: ='ग्रामनिधी ३-४ '!BX17 -> 0
A31: 1 | B31: बाजार फी | C31: ०२०६-१०१ | D31: ='ग्रामनिधी ३-४ '!AL13 -> 0 | E31: 13 | F31: आरोग्य | G31: 22104210 | H31: ='ग्रामनिधी ३-४ '!BW18+'पाणीपट्टी ३-४'!BW18 -> 2 | I31: ='ग्रामनिधी ३-४ '!BX18+'पाणीपट्टी ३-४'!BX18 -> 0
A32: 2 | B32: टांगा थांबा फी | C32: ००४५-८०० | D32: 0 | E32: 14 | F32: रस्ते व गटार
A33: 3 | B33: कार थांबा फी | C33: ००४५-८०० | D33: 0 | F33: रस्ते देखभाल दुरुस्ती | G33: ३०५४-१०१-२७ | H33: ='ग्रामनिधी ३-४ '!BW19 -> 2 | I33: ='ग्रामनिधी ३-४ '!BX19 -> 0
A34: 4 | B34: पाणी पट्टी | F34: रस्ते नवीन | G34: ५०५४-१०१-५३ | H34: ='ग्रामनिधी ३-४ '!BW20 -> 2 | I34: ='ग्रामनिधी ३-४ '!BX20 -> 0
B35: जनरल पाणीपट्टी | C35: ०२१५-८०० | D35: ='पाणीपट्टी ३-४'!AL5 -> 0 | F35: गटार देखभाल दुरुस्ती | G35: २०५९-१०१-२७ | H35: ='ग्रामनिधी ३-४ '!BW21 -> 2 | I35: ='ग्रामनिधी ३-४ '!BX21 -> 0
B36: स्पेशल पाणीपट्टी | C36: ०२१५-१०१ | D36: ='पाणीपट्टी ३-४'!AL6 -> 0 | F36: गटार नवीन | G36: ५०५४-१०२-५३ | H36: ='ग्रामनिधी ३-४ '!BW22 -> 2 | I36: ='ग्रामनिधी ३-४ '!BX22 -> 0
A37: 5 | B37: स्वच्छता फी | C37: ०२१५-१०३ | D37: 0 | E37: 15 | F37: अन्य बांधकाम
A38: 6 | B38: गाय चरण फी | C38: ०४०३-१०४ | D38: 0 | F38: मुतारी दुरुस्ती | H38: ='ग्रामनिधी ३-४ '!BW23 -> 2 | I38: ='ग्रामनिधी ३-४ '!BX23 -> 0
A39: 7 | B39: डीव्हीडीएफ व्याज २.५ % | C39: ००४९-८०० | D39: 0 | F39: स्मशानभूमी दुरुस्ती | H39: ='ग्रामनिधी ३-४ '!BW24 -> 2 | I39: ='ग्रामनिधी ३-४ '!BX24 -> 0
A40: 8 | B40: जमीन भाडेपट्टी | C40: ०५१५-४२ | D40: ='ग्रामनिधी ३-४ '!AL14 -> 0
A41: 9 | B41: व्याज जमा | C41: ००४९-१०१ | D41: ='ग्रामनिधी ३-४ '!AL15+'पाणीपट्टी ३-४'!AL12 -> 0
...

Sheet ग्रामनिधी ३-४ 
B2: ग्राम पंचायत | C2: ='मुख्य पान '!E2 -> बळसाणे | AL2: ता. | AM2: ='मुख्य पान '!I2 -> साक्री | AN2: जि. | BW2: ='मुख्य पान '!M2 -> धुळे
B3: सन | AM3: ग्रामनिधी नमुना न. ३/४
B4: जमा बाजू | AL4: एकूण जमा | AM4: खर्च बाजू | BW4: एकूण खर्च
B5: निवासी इमारतीवरील कर | C5: ००३५-१०१ | AJ5: =SUM(E5:AI5) -> 0 | AK5: =[1]Feb!AL7 -> 138149 | AL5: =March!AL8 -> 0 | AM5: सरपंच मानधन | AN5: २५१५-१०३-०५ | BU5: =SUM(AP5:BT5) -> 0 | BV5: =[1]Feb!AL49 -> 0 | BW5: =March!AL50 -> 2
B6: अनिवासी इमारती, खुल्या ( अकृषक ) जागेवरील कर | C6: ००३५-१०२ | AJ6: =SUM(E6:AI6) -> 0 | AK6: =[1]Feb!AL8 -> 0 | AL6: =March!AL9 -> 0 | AM6: सदस्य बैठक भत्ता | AN6: १६०१-१०२-२०५३-१०४२-३१ | BU6: =SUM(AP6:BT6) -> 0 | BV6: =[1]Feb!AL50 -> 0 | BW6: =March!AL51 -> 2
B7: दिवाबत्ती | C7: ००४४-१०१ | AJ7: =SUM(E7:AI7) -> 0 | AK7: =[1]Feb!AL9 -> 10192 | AL7: =March!AL10 -> 0 | AM7: सदस्य / सरपंच प्रवास भत्ता | AN7: २५१५-१०३-११ | BU7: =SUM(AP7:BT7) -> 0 | BV7: =[1]Feb!AL51 -> 0 | BW7: =March!AL52 -> 2
B8: स्वच्छता कर | C8: ०२१५-१०३ | AJ8: =SUM(E8:AI8) -> 0 | AK8: =[1]Feb!AL10 -> 9453 | AL8: =March!AL11 -> 0 | AM8: कर्मचारी वेतन | AN8: २५१५-१०३-०१ | BU8: =SUM(AP8:BT8) -> 0 | BV8: =[1]Feb!AL52 -> 75075 | BW8: =March!AL53 -> 2
B9: दुकाने, लघु उद्योग व हॉटेल चालविणे यावरील कर | C9: ००२८-१०२ | AJ9: =SUM(E9:AI9) -> 0 | AK9: =[1]Feb!AL11 -> 0 | AL9: =March!AL12 -> 0 | AM9: कर्मचारी प्रवास भत्ता | AN9: २५१५-१०३-A११ | BU9: =SUM(AP9:BT9) -> 0 | BV9: =[1]Feb!AL53 -> 0 | BW9: =March!AL54 -> 2
B10: यात्रा कर | C10: ००४२-१०३ | AJ10: =SUM(E10:AI10) -> 0 | AK10: =[1]Feb!AL12 -> 0 | AL10: =March!AL13 -> 0 | AM10: कार्यालयीन खर्च | AN10: २५१५-१०३-१३ | BU10: =SUM(AP10:BT10) -> 0 | BV10: =[1]Feb!AL54 -> 15696 | BW10: =March!AL55 -> 2
B11: जत्रा व उत्सव कर | C11: ०२०६-१०२ | AJ11: =SUM(E11:AI11) -> 0 | AK11: =[1]Feb!AL13 -> 0 | AL11: =March!AL14 -> 0 | AM11: दुरुस्ती व देखभाल | AN11: २०५९-१०१-२७ | BU11: =SUM(AP11:BT11) -> 0 | BV11: =[1]Feb!AL55 -> 0 | BW11: =March!AL56 -> 2
B12: इतर ( वर्गणी ) | AJ12: =SUM(E12:AI12) -> 0 | AK12: =[1]Feb!AL14 -> 0 | AL12: =March!AL15 -> 0 | AM12: स्वच्छता | AN12: 2215 | BU12: =SUM(AP12:BT12) -> 0 | BV12: =[1]Feb!AL56 -> 75300 | BW12: =March!AL57 -> 2
B13: बाजार फी | C13: ०२०६-१०१ | AJ13: =SUM(E13:AI13) -> 0 | AK13: =[1]Feb!AL15 -> 0 | AL13: =March!AL16 -> 0 | AM13: ( ब ) रस्त्यावरील दिवाबत्ती | AN13: १६०१-१०२-३६०४-०३२५-५० | BU13: =SUM(AP13:BT13) -> 0 | BV13: =[1]Feb!AL57 -> 0 | BW13: =March!AL58 -> 2
B14: जमीन भाडेपट्टी | C14: ०५१५-४२ | AJ14: =SUM(E14:AI14) -> 0 | AK14: =[1]Feb!AL16 -> 0 | AL14: =March!AL17 -> 0 | AM14: ( क ) कार्यालय | AN14: २८०१-१०१-२१ | BU14: =SUM(AP14:BT14) -> 0 | BV14: =[1]Feb!AL58 -> 0 | BW14: =March!AL59 -> 2
B15: व्याज जमा | C15: ००४९-१०१ | AJ15: =SUM(E15:AI15) -> 0 | AK15: =[1]Feb!AL17 -> 781 | AL15: =March!AL18 -> 0 | AM15: पथ दिवाबत्ती, साहित्य व इतर | AN15: २८०१-१०३-२१ | BU15: =SUM(AP15:BT15) -> 0 | BV15: =[1]Feb!AL59 -> 25717 | BW15: =March!AL60 -> 2
B16: जागा भाडे | C16: ०५१५-४२ | AJ16: =SUM(E16:AI16) -> 0 | AK16: =[1]Feb!AL18 -> 0 | AL16: =March!AL19 -> 0 | AM16: दिवाबत्ती मजुरी | AN16: २८०१-१०३-०२ | BU16: =SUM(AP16:BT16) -> 0 | BV16: =[1]Feb!AL60 -> 7000 | BW16: =March!AL61 -> 2
B17: देणगी | C17: ०५१५-८०० | AJ17: =SUM(E17:AI17) -> 0 | AK17: =[1]Feb!AL19 -> 0 | AL17: =March!AL20 -> 0 | AM17: शिक्षण | AN17: 22024202 | BU17: =SUM(AP17:BT17) -> 0 | BV17: =[1]Feb!AL61 -> 0 | BW17: =March!AL62 -> 2
B18: इतर जमा | C18: ०५१५-८०० | AJ18: =SUM(E18:AI18) -> 0 | AK18: =[1]Feb!AL20 -> 10000 | AL18: =March!AL21 -> 0 | AM18: आरोग्य | AN18: 22104210 | BU18: =SUM(AP18:BT18) -> 0 | BV18: =[1]Feb!AL62 -> 13000 | BW18: =March!AL63 -> 2
B19: लिलाव ( धूळ, घाण, शेण, केरकचरा, जनावरांची प्रेत व इतर) | C19: ०५१५-८०० | AJ19: =SUM(E19:AI19) -> 0 | AK19: =[1]Feb!AL21 -> 0 | AL19: =March!AL22 -> 0 | AM19: रस्ते देखभाल दुरुस्ती | AN19: ३०५४-१०१-२७ | BU19: =SUM(AP19:BT19) -> 0 | BV19: =[1]Feb!AL63 -> 73400 | BW19: =March!AL64 -> 2
B20: इमारत भाडे ( टावर भाडे ) | C20: ००५९-१०१ | AJ20: =SUM(E20:AI20) -> 0 | AK20: =[1]Feb!AL22 -> 10520 | AL20: =March!AL23 -> 0 | AM20: रस्ते नवीन | AN20: ५०५४-१०१-५३ | BU20: =SUM(AP20:BT20) -> 0 | BV20: =[1]Feb!AL64 -> 0 | BW20: =March!AL65 -> 2
B21: दाखले फी | C21: ०५१५-४६ | AJ21: =SUM(E21:AI21) -> 0 | AK21: =[1]Feb!AL23 -> 0 | AL21: =March!AL24 -> 0 | AM21: गटार देखभाल दुरुस्ती | AN21: २०५९-१०१-२७ | BU21: =SUM(AP21:BT21) -> 0 | BV21: =[1]Feb!AL65 -> 65000 | BW21: =March!AL66 -> 2
B22: मुद्रांक शुल्क | C22: ००३०-९०१ | AJ22: =SUM(E22:AI22) -> 0 | AK22: =[1]Feb!AL24 -> 32850 | AL22: =March!AL25 -> 0 | AM22: गटार नवीन | AN22: ५०५४-१०२-५३ | BU22: =SUM(AP22:BT22) -> 0 | BV22: =[1]Feb!AL66 -> 0 | BW22: =March!AL67 -> 2
B23: उपकर | C23: ००२९-१०२ | AJ23: =SUM(E23:AI23) -> 0 | AK23: =[1]Feb!AL25 -> 2578 | AL23: =March!AL26 -> 0 | AM23: मुतारी दुरुस्ती | BU23: =SUM(AP23:BT23) -> 0 | BV23: =[1]Feb!AL67 -> 7400 | BW23: =March!AL68 -> 2
B24: जमीन महसूल | C24: ००२९-१०१ | AJ24: =SUM(E24:AI24) -> 0 | AK24: =[1]Feb!AL26 -> 53100 | AL24: =March!AL27 -> 0 | AM24: स्मशानभूमी दुरुस्ती | BU24: =SUM(AP24:BT24) -> 0 | BV24: =[1]Feb!AL68 -> 0 | BW24: =March!AL69 -> 2
B25: जमीन समानीकरण | C25: ००२९-९०१ | AJ25: =SUM(E25:AI25) -> 0 | AK25: =[1]Feb!AL27 -> 8775 | AL25: =March!AL28 -> 0 | AM25: समाजकल्याण ( २०%) ( आदिवासी व मागास वर्ग ) | AN25: २२३५-१०१-३२ | BU25: =SUM(AP25:BT25) -> 0 | BV25: =[1]Feb!AL69 -> 8880 | BW25: =March!AL70 -> 2
B26: गौण खनिज | C26: ०५१५-९०१ | AJ26: =SUM(E26:AI26) -> 0 | AK26: =[1]Feb!AL28 -> 27500 | AL26: =March!AL29 -> 0 | AM26: अनामत / प्रतीभुती | AN26: ८४४३-१०२-५५ | BU26: =SUM(AP26:BT26) -> 0 | BV26: =[1]Feb!AL70 -> 97000 | BW26: =March!AL71 -> 2
B27: इतर अनुदान ( शिपाई पगार मानधन ) | AJ27: =SUM(E27:AI27) -> 0 | AK27: =[1]Feb!AL29 -> 48097 | AL27: =March!AL30 -> 0 | AM27: महिला व बाल कल्याण ( १० % ) | AN27: २२११-१०१-३२ | BU27: =SUM(AP27:BT27) -> 0 | BV27: =[1]Feb!AL71 -> 8900 | BW27: =March!AL72 -> 2
B28: मानधन, किमान वेतन व बैठक भत्ता | C28: १६०१-१०२-२०५३-२०४२-३१ | AJ28: =SUM(E28:AI28) -> 0 | AK28: =[1]Feb!AL30 -> 80325 | AL28: =March!AL31 -> 0 | AM28: साहित्य खरेदी | AN28: २५१५-१०३-२१ | BU28: =SUM(AP28:BT28) -> 0 | BV28: =[1]Feb!AL72 -> 0 | BW28: =March!AL73 -> 2
B29: इतर | C29: ४०००-८०० | AJ29: =SUM(E29:AI29) -> 0 | AK29: =[1]Feb!AL31 -> 3400 | AL29: =March!AL32 -> 0 | AM29: अपंग कल्याण | AN29: २२३५-१०२-६२ | BU29: =SUM(AP29:BT29) -> 0 | BV29: =[1]Feb!AL73 -> 0 | BW29: =March!AL74 -> 2
B30: आमदार निधी | C30: १६०१-१०२ | AJ30: =SUM(E30:AI30) -> 0 | AK30: =[1]Feb!AL32 -> 194035 | AL30: =March!AL33 -> 0 | AM30: कर्म. भविष्य निर्वाह निधी | AN30: ८००९-१०२-५६ | BU30: =SUM(AP30:BT30) -> 0 | BV30: =[1]Feb!AL74 -> 12600 | BW30: =March!AL75 -> 22
B31: खासदार निधी | C31: ४५१५-२५५३-१०१-२५ | AJ31: =SUM(E31:AI31) -> 0 | AK31: =[1]Feb!AL33 -> 0 | AL31: =March!AL34 -> 0 | AM31: मानधन, किमान वेतन व बैठक भत्ता व अल्पोपहार | AN31: १६०१-१०२-२०५३-१०४२-३१ | BU31: =SUM(AP31:BT31) -> 0 | BV31: =[1]Feb!AL75 -> 0 | BW31: =March!AL76 -> 2
B32: अनामत / प्रतीभुती | C32: ८४४३-१०२-५५ | AJ32: =SUM(E32:AI32) -> 0 | AK32: =[1]Feb!AL34 -> 104161 | AL32: =March!AL35 -> 0 | AM32: आमदार निधी | AN32: १६०१-१०२ | BU32: =SUM(AP32:BT32) -> 0 | BV32: =[1]Feb!AL76 -> 194000 | BW32: =March!AL77 -> 2
B33: ठेवी | C33: ८४४३-१०३-५५ | AJ33: =SUM(E33:AI33) -> 0 | AK33: =[1]Feb!AL35 -> 0 | AL33: =March!AL36 -> 0 | AM33: खासदार निधी | AN33: ४५१५-२५५३-१०१-२५ | BU33: =SUM(AP33:BT33) -> 0 | BV33: =[1]Feb!AL77 -> 0 | BW33: =March!AL78 -> 2
AL34: =March!AL37 -> 0 | AM34: इतर बँक चार्जेस | BW34: =March!AL79 -> 2
AL35: =March!AL38 -> 0 | AM35: वर्ग रकमा | BW35: =March!AL80 -> 2
AL36: =March!AL39 -> 0 | BW36: 0
AL37: =March!AL40 -> 0 | BW37: =March!AL82 -> 0
B38: एकूण जमा | AH38: एकूण | AJ38: =SUM(AJ5:AJ33) -> 0 | AK38: =SUM(AK5:AK33) -> 733916 | AL38: =SUM(AL5:AL33) -> 0 | AM38: एकूण खर्च | BU38: =SUM(AP38:BT38) -> 0 | BV38: =[1]Feb!AL78 -> 1062 | BW38: =SUM(BW5:BW37) -> 82
B39: सुरवातीची शिल्लक | AI39: वर्षारंभीची शिल्लक | AK39: =March!AK38 -> 1000 | AM39: अखेरची शिल्लक | BU39: =SUM(AP39:BT39) -> 0 | BV39: =[1]Feb!AL79 -> 72600 | BW39: =March!AK42 -> 918
AI40: महिन्यातील जमा | AK40: =AL38 -> 0 | BS40: एकूण | BU40: =SUM(BU5:BU39) -> 0 | BV40: =SUM(BV5:BV39) -> 752630 | BW40: =SUM(BW5:BW39) -> 1082
B41: एकूण एकंदर | AI41: एकूण एकंदर | AK41: =SUM(AK39:AL40) -> 1000 | AM41: एकूण एकंदर | BW41: =SUM(BW38:BW39) -> 1000
...

Sheet पाणीपट्टी ३-४
B2: ग्राम पंचायत | C2: ='मुख्य पान '!E2 -> बळसाणे | AL2: ता. | AM2: ='मुख्य पान '!I2 -> साक्री | AN2: जि. | BW2: ='मुख्य पान '!M2 -> धुळे
B3: सन | AM3: पाणी पुरवठा नमुना न. ३/४
B4: जमा बाजू | AL4: एकूण जमा | AM4: खर्च बाजू | BW4: एकूण खर्च
B5: ='P-March'!B8 -> जनरल पाणीपट्टी | C5: ='P-March'!C8 -> ०२१५-८०० | AJ5: =SUM(E5:AI5) -> 0 | AK5: =[1]Feb!AL7 -> 138149 | AL5: ='P-March'!AL8 -> 0 | AM5: ='P-March'!B50 -> कर्मचारी वेतन | AN5: ='P-March'!C50 -> २५१५-१०३-०१ | BU5: =SUM(AP5:BT5) -> 0 | BV5: =[1]Feb!AL49 -> 0 | BW5: ='P-March'!AL50 -> 1000
B6: ='P-March'!B9 -> स्पेशल पाणीपट्टी | C6: ='P-March'!C9 -> ०२१५-१०१ | AJ6: =SUM(E6:AI6) -> 0 | AK6: =[1]Feb!AL8 -> 0 | AL6: ='P-March'!AL9 -> 0 | AM6: ='P-March'!B51 -> कर्मचारी प्रवास भत्ता | AN6: ='P-March'!C51 -> २५१५-१०३-A११ | BU6: =SUM(AP6:BT6) -> 0 | BV6: =[1]Feb!AL50 -> 0 | BW6: ='P-March'!AL51 -> 0
B7: ='P-March'!B10 -> पाईप लाईन दुरुस्ती | C7: ='P-March'!C10 -> २२१५-१०१-०२ | AJ7: =SUM(E7:AI7) -> 0 | AK7: =[1]Feb!AL9 -> 10192 | AL7: ='P-March'!AL10 -> 0 | AM7: ='P-March'!B52 -> दुरुस्ती व देखभाल | AN7: ='P-March'!C52 -> २०५९-१०१-२७ | BU7: =SUM(AP7:BT7) -> 0 | BV7: =[1]Feb!AL51 -> 0 | BW7: ='P-March'!AL52 -> 0
B8: ='P-March'!B11 -> पाणी पुरवठा नवीन कामे | C8: ='P-March'!C11 -> ४२१५-१०२-५३ | AJ8: =SUM(E8:AI8) -> 0 | AK8: =[1]Feb!AL10 -> 9453 | AL8: ='P-March'!AL11 -> 0 | AM8: ='P-March'!B53 -> स्वच्छता | AN8: ='P-March'!C53 -> 2215 | BU8: =SUM(AP8:BT8) -> 0 | BV8: =[1]Feb!AL52 -> 75075 | BW8: ='P-March'!AL53 -> 0
B9: ='P-March'!B12 -> पाणी पुरवठा कर्मचारी वेतन | C9: ='P-March'!C12 -> २२१५-१०३-०१ | AJ9: =SUM(E9:AI9) -> 0 | AK9: =[1]Feb!AL11 -> 0 | AL9: ='P-March'!AL12 -> 0 | AM9: ='P-March'!B54 -> पाईप लाईन दुरुस्ती | AN9: ='P-March'!C54 -> २२१५-१०१-०२ | BU9: =SUM(AP9:BT9) -> 0 | BV9: =[1]Feb!AL53 -> 0 | BW9: ='P-March'!AL54 -> 0
B10: ='P-March'!B13 -> नळ पाणी पुरवठ्यातील देयकासाठी ५०% अनुदान | C10: ='P-March'!C13 -> १६०१-१०२ | AJ10: =SUM(E10:AI10) -> 0 | AK10: =[1]Feb!AL12 -> 0 | AL10: ='P-March'!AL13 -> 0 | AM10: ='P-March'!B55 -> पाणी पुरवठा नवीन कामे | AN10: ='P-March'!C55 -> ४२१५-१०२-५३ | BU10: =SUM(AP10:BT10) -> 0 | BV10: =[1]Feb!AL54 -> 15696 | BW10: ='P-March'!AL55 -> 0
B11: ='P-March'!B14 -> इतर ( वर्गणी ) | C11: ='P-March'!C14 -> 0 | AJ11: =SUM(E11:AI11) -> 0 | AK11: =[1]Feb!AL13 -> 0 | AL11: ='P-March'!AL14 -> 0 | AM11: ='P-March'!B56 -> पाणी पुरवठा कर्मचारी वेतन | AN11: ='P-March'!C56 -> २२१५-१०३-०१ | BU11: =SUM(AP11:BT11) -> 0 | BV11: =[1]Feb!AL55 -> 0 | BW11: ='P-March'!AL56 -> 0
B12: ='P-March'!B15 -> व्याज जमा | C12: ='P-March'!C15 -> ००४९-१०१ | AJ12: =SUM(E12:AI12) -> 0 | AK12: =[1]Feb!AL14 -> 0 | AL12: ='P-March'!AL15 -> 0 | AM12: ='P-March'!B57 -> पाणी मीटर / साहित्य खरेदी | AN12: ='P-March'!C57 -> २२१५-१०१-२१ | BU12: =SUM(AP12:BT12) -> 0 | BV12: =[1]Feb!AL56 -> 75300 | BW12: ='P-March'!AL57 -> 0
B13: ='P-March'!B16 -> देणगी | C13: ='P-March'!C16 -> ०५१५-८०० | AJ13: =SUM(E13:AI13) -> 0 | AK13: =[1]Feb!AL15 -> 0 | AL13: ='P-March'!AL16 -> 0 | AM13: ='P-March'!B58 -> नळमार्गाचे परीक्षण व दुरुस्ती | AN13: ='P-March'!C58 -> २२१५-१०१-२७ | BU13: =SUM(AP13:BT13) -> 0 | BV13: =[1]Feb!AL57 -> 0 | BW13: ='P-March'!AL58 -> 0
B14: ='P-March'!B17 -> इतर जमा | C14: ='P-March'!C17 -> ०५१५-८०० | AJ14: =SUM(E14:AI14) -> 0 | AK14: =[1]Feb!AL16 -> 0 | AL14: ='P-March'!AL17 -> 0 | AM14: ='P-March'!B59 -> शासकीय पाणीपट्टीचा भरणा करणे | AN14: ='P-March'!C59 -> २२१५-१०१-१४ | BU14: =SUM(AP14:BT14) -> 0 | BV14: =[1]Feb!AL58 -> 0 | BW14: ='P-March'!AL59 -> 0
B15: ='P-March'!B18 -> लिलाव (पाणी पुरवठा साहित्य ) | C15: ='P-March'!C18 -> ०५१५-८०० | AJ15: =SUM(E15:AI15) -> 0 | AK15: =[1]Feb!AL17 -> 781 | AL15: ='P-March'!AL18 -> 0 | AM15: ='P-March'!B60 -> नलिका विहिरीची देखभाल व दुरुस्ती | AN15: ='P-March'!C60 -> २२१५-१०२-२७ | BU15: =SUM(AP15:BT15) -> 0 | BV15: =[1]Feb!AL59 -> 25717 | BW15: ='P-March'!AL60 -> 0
B16: ='P-March'!B19 -> बांधकाम | C16: ='P-March'!C19 -> १६०१-१०२-५३ | AJ16: =SUM(E16:AI16) -> 0 | AK16: =[1]Feb!AL18 -> 0 | AL16: ='P-March'!AL19 -> 0 | AM16: ='P-March'!B61 -> हात पंप / वीज पंप वर्गणी | AN16: ='P-March'!C61 -> २२१५-१०२-३२ | BU16: =SUM(AP16:BT16) -> 0 | BV16: =[1]Feb!AL60 -> 7000 | BW16: ='P-March'!AL61 -> 0
... B33: ='P-March'!B36 | C33: ='P-March'!C36 | AJ33: =SUM(E33:AI33) -> 0 | AK33: =[1]Feb!AL35 -> 0 | AL33: ='P-March'!AL36 -> 0 | AM33: ='P-March'!B78 -> 0 | AN33: ='P-March'!C78 -> 0 | BU33: =SUM(AP33:BT33) -> 0 | BV33: =[1]Feb!AL77 -> 0 | BW33: ='P-March'!AL78 -> 0
B34: ='P-March'!B37 -> 0 | C34: ='P-March'!C37 -> 0 | AM34: ='P-March'!B79 | AN34: ='P-March'!C79
B35: ='P-March'!B38 -> 0 | C35: ='P-March'!C38 -> 0 | AM35: ='P-March'!B80 | AN35: ='P-March'!C80
B36: ='P-March'!B39 -> 0 | C36: ='P-March'!C39 -> 0 | AM36: ='P-March'!B81 -> 0 | AN36: ='P-March'!C81 -> 0
B37: ='P-March'!B40 -> 0 | C37: ='P-March'!C40 -> 0 | AM37: ='P-March'!B82 -> 0 | AN37: ='P-March'!C82 -> 0
B38: एकूण जमा | AH38: एकूण | AJ38: =SUM(AJ5:AJ33) -> 0 | AK38: =SUM(AK5:AK33) -> 733916 | AL38: =SUM(AL5:AL37) -> 0 | AM38: एकूण खर्च | BU38: =SUM(AP38:BT38) -> 0 | BV38: =[1]Feb!AL78 -> 1062 | BW38: =SUM(BW5:BW37) -> 1000
B39: सुरवातीची शिल्लक | AI39: वर्षारंभीची शिल्लक | AK39: ='P-March'!AK38:AL38 -> 1234 | AM39: अखेरची शिल्लक | BU39: =SUM(AP39:BT39) -> 0 | BV39: =[1]Feb!AL79 -> 72600 | BW39: ='P-March'!AK42 -> 234
AI40: महिन्यातील जमा | AK40: =AL38 -> 0 | BS40: एकूण | BU40: =SUM(BU5:BU39) -> 0 | BV40: =SUM(BV5:BV39) -> 752630 | BW40: =SUM(BW5:BW39) -> 2234
B41: एकूण एकंदर | AI41: एकूण एकंदर | AK41: =SUM(AK39:AL40) -> 1234 | AM41: एकूण एकंदर | BW41: =SUM(BW38:BW39) -> 1234
AI42: महिन्यातील खर्च | AK42: =BW40 -> 2234
AI43: अखेरची शिल्लक | AK43: =AK41-AK42 -> -1000
AK44: =SUM(AK42:AL43) -> 1234
A45: नमूना नं. ०६
A46: सन २०१७/२०१८ [ नियम १९(७), २५(१), (२) व (३), ३२(५), व (६), ३३ (२) (३) व (४) (च), ३५, ३६,(२), ३८(१), ४२(४), (ध), ६३ (२) आणि (४) पाहा ]
B47: माहे | C47: मार्च | D47: महिन्याबद्दल खर्च रक्कमांची वर्गीकृत नोंदवही | AK47: पान क्रं.
B48: ग्राम पंचायत | D48: भडणे | G48: ता. | J48: शिंदखेडा | Y48: जि. | AA48: धुळे
F76: वकील जामसिंग भिल
E77: सरकार | F77: रामसिंग जामसिंग भिल
D78: 60
D79: 61
D80: 62
D81: 63
D82: 64
D83: 65
D84: 66
...

Sheet न.नं.५ योजना
A1: सामान्य कॅशबुक नमुना नं. ५
A2: ग्राम पंचायत | E2: ता. | H2: सन | K2: २०२१/२२
A3: जमा बाजू | O3: खर्च बाजू
A4: दिनांक | B4: पावती नंबर | C4: जमेचा तपशील | E4: लेखाशीर्ष | F4: जमा रक्कम | G4: सुरवातीच्या शिल्लक सहित रोजची एकूण जमा | H4: अदा केल्याची तारिख | I4: चेक क्र. | J4: व्हौचर क्र. | K4: अदा केल्याचा तपशील | M4: लेखाशीर्ष | N4: खर्च रक्कम | O4: अखेरच्या शिल्लक सहित रोजची एकूण रु .
C5: कोणाकडून मिळाले | D5: कोणत्या खात्यावर | K5: कोणास अदा केले | L5: कोणत्या खात्यावर
F6: आरंभीची शिल्लक | N6: 100
F7: 1000
F8: 1000 | N8: 100
F9: 10 | N9: 100
N10: 100
F11: 100
F15: 1
F19: एकूण जमा | G19: =SUM(F7:F18) -> 2111 | I19: DDC बँकेत | K19: =G31 -> 500 | M19: आजचा खर्च | O19: =SUM(N6:N18) -> 400
F20: एकूण एकंदर | G20: =G6+G19 -> 2111 | I20: बँक | K20: =G32 -> 300 | M20: अखेरची शिल्लक | O20: =O21-O19 -> 1711
I21: हाती शिल्लक | K21: =T29-K19-K20 -> 911 | M21: एकूण एकंदर | O21: =G20 -> 2111
I22: अखेरची शिल्लक | K22: =O20 -> 1711
H23: अक्षरी रक्कम रु. | K23: =IFERROR(IF(LEN(T25)>11,LMT,IF(VALUE(RIGHT(INT(T25/ABJ),2))=0,"",INDEX(MA_Num_S2G,RIGHT(INT(T25/ABJ),2)) &ABW)&IF(VALUE(RIGHT(INT(T25/KTI),2))=0,"",INDEX(MA_Num_S2G,RIGHT(INT(T25/KTI),2))&KTW)&IF(VALUE(RIGHT(INT(T25/LKS),2))=0,"",INDEX(MA_Num_S2G,RIGHT(INT(T25/LKS),2))&LKW)&IF(VALUE(RIGHT(INT(T25/HZR),2))=0,"",INDEX(MA_Num_S2G,RIGHT(INT(T25/HZR),2))&HZW)&IF(RIGHT(T25,3)="100",STK,IF(VALUE(RIGHT(INT(T25/100),1))=0,"",INDEX(MA_Num_S2G,RIGHT(INT(T25/100),1))&SHE))&IF(INT(RIGHT(T25,2))=0,"",INDEX(MA_Num_S2G,RIGHT(T25,2)))&IF(T25=0,ZRO,"")),"") -> एक हजार सातशे अकरा
T25: =K22 -> 1711
G28: 1000 | T28: =G20 -> 2111 | U28: =O20 -> 1711
T29: =K22 -> 1711
F31: DDCC बँक | G31: 500
F32: इतर बँक | G32: 300
F76: वकील जामसिंग भिल
E77: सरकार | F77: रामसिंग जामसिंग भिल
D78: 60
D79: 61
D80: 62
D81: 63
D82: 64
D83: 65
D84: 66
D85: 67
D86: 68
D87: 68
D88: 69
D89: 70
... D118: 99
D119: 99 | E119: सरकार
D120: 100
D121: 101
...

Sheet Sheet1
B4: Gramnidhi_Jama | C4: Gramnidhi_kharch | D4: Panipatti_jama | E4: Panipatti_kharch
B5: निवासी इमारतीवरील कर | C5: सरपंच मानधन | D5: जनरल पाणीपट्टी | E5: कर्मचारी वेतन
B6: अनिवासी इमारती, खुल्या ( अकृषक ) जागेवरील कर | C6: सदस्य बैठक भत्ता | D6: स्पेशल पाणीपट्टी | E6: कर्मचारी प्रवास भत्ता
B7: दिवाबत्ती | C7: सदस्य / सरपंच प्रवास भत्ता | D7: पाणी पुरवठा | E7: दुरुस्ती व देखभाल
B8: स्वच्छता कर | C8: कर्मचारी वेतन | D8: पाईप लाईन दुरुस्ती | E8: स्वच्छता
B9: दुकाने, लघु उद्योग व हॉटेल चालविणे यावरील कर | C9: कर्मचारी प्रवास भत्ता | D9: पाणी पुरवठा नवीन कामे | E9: पाईप लाईन दुरुस्ती
B10: यात्रा कर | C10: कार्यालयीन खर्च | D10: पाणी पुरवठा कर्मचारी वेतन | E10: पाणी पुरवठा नवीन कामे
B11: जत्रा व उत्सव कर | C11: दुरुस्ती व देखभाल | D11: पाणी मीटर / साहित्य खरेदी | E11: पाणी पुरवठा कर्मचारी वेतन
B12: इतर ( वर्गणी ) | C12: स्वच्छता | D12: नळमार्गाचे परीक्षण व दुरुस्ती | E12: पाणी मीटर / साहित्य खरेदी
B13: बाजार फी | C13: ( ब ) रस्त्यावरील दिवाबत्ती | D13: शासकीय पाणीपट्टीचा भरणा करणे | E13: नळमार्गाचे परीक्षण व दुरुस्ती
B14: जमीन भाडेपट्टी | C14: ( क ) कार्यालय | D14: नलिका विहिरीची देखभाल व दुरुस्ती | E14: शासकीय पाणीपट्टीचा भरणा करणे
B15: व्याज जमा | C15: पथ दिवाबत्ती, साहित्य व इतर | D15: हात पंप / वीज पंप वर्गणी | E15: नलिका विहिरीची देखभाल व दुरुस्ती
... B29: इतर | C29: अपंग कल्याण | D29: केंद्र शासन कर्ज | E29: अग्रिम / अनामत
B30: आमदार निधी | C30: कर्म. भविष्य निर्वाह निधी | E30: ठेवी
B31: खासदार निधी | C31: मानधन, किमान वेतन व बैठक भत्ता व अल्पोपहार | E31: राज्य शासन कर्जे, हफ्ता व व्याज प्रदाने
B32: २५१५ स्थानिक विकास निधी | C32: आमदार निधी | E32: केंद्र शासन कर्जे, हफ्ता व व्याज प्रदाने
B33: अनामत / प्रतीभुती | C33: खासदार निधी | E33: इतर
B34: ठेवी | C34: अग्रिम / अनामत | E34: अनामत / प्रतीभुती
C35: ठेवी | E35: बँक चार्जेस
C36: अनामत / प्रतीभुती | E36: वर्ग रकमा
C37: बँक चार्जेस
C38: वर्ग रकमा
C39: सिमेंट रस्ता तयार करणे
C40: अमरधाम बांधकाम करणे
C41: पेव्हर ब्लॉक बसविणे

Sheet न.नं.५ पा. पु
A1: सामान्य कॅशबुक नमुना नं. ५
A2: ग्राम पंचायत | J2: ता. | M2: सन | P2: २०२१/२२
A3: जमा बाजू | T3: खर्च बाजू
A4: दिनांक | B4: पावती क्र. | C4: कोणाकडून मिळाले | D4: जमेचा तपशील | J4: लेखाशीर्ष | K4: जमा रक्कम | L4: सुरवातीच्या शिल्लक सहित रोजची एकूण जमा | M4: अदा केल्याची तारिख | N4: चेक क्र. | O4: व्हौचर क्र. | P4: अदा केल्याचा तपशील | R4: लेखाशीर्ष | S4: खर्च रक्कम | T4: अखेरच्या शिल्लक सहित रोजची एकूण रु .
D5: जनरल पाणी पट्टी | G5: स्पेशल पाणी पट्टी
D6: मागील | E6: चालू | F6: एकूण | G6: मागील | H6: चालू | I6: एकूण | P6: कोणास अदा केले | Q6: कोणत्या खात्यावर
F7: =D7+E7 -> 0 | I7: =G7+H7 -> 0 | K7: आरंभीची शिल्लक
F8: =D8+E8 -> 0 | I8: =G8+H8 -> 0 | K8: =F8+I8 -> 0
F9: =D9+E9 -> 0 | I9: =G9+H9 -> 0 | K9: =F9+I9 -> 0
F10: =D10+E10 -> 0 | I10: =G10+H10 -> 0 | K10: =F10+I10 -> 0
F11: =D11+E11 -> 0 | I11: =G11+H11 -> 0 | K11: =F11+I11 -> 0
D12: 1000 | F12: =D12+E12 -> 1000 | I12: =G12+H12 -> 0 | K12: =F12+I12 -> 1000
F13: =D13+E13 -> 0 | I13: =G13+H13 -> 0 | K13: =F13+I13 -> 0
F14: =D14+E14 -> 0 | I14: =G14+H14 -> 0 | K14: =F14+I14 -> 0
F15: =D15+E15 -> 0 | I15: =G15+H15 -> 0 | K15: =F15+I15 -> 0
F16: =D16+E16 -> 0 | I16: =G16+H16 -> 0 | K16: =F16+I16 -> 0
F17: =D17+E17 -> 0 | I17: =G17+H17 -> 0 | K17: =F17+I17 -> 0
F18: =D18+E18 -> 0 | I18: =G18+H18 -> 0 | K18: =F18+I18 -> 0
C19: एकूण | D19: =SUM(D7:D18) -> 1000 | E19: =SUM(E7:E18) -> 0 | F19: =SUM(F7:F18) -> 1000 | G19: =SUM(G7:G18) -> 0 | H19: =SUM(H7:H18) -> 0 | I19: =SUM(I7:I18) -> 0
K20: एकूण जमा | L20: =SUM(K8:K19) -> 1000 | N20: DDCबँकेत | P20: =L33 -> 500 | R20: आजचा खर्च | T20: =SUM(S7:S19) -> 0
K21: एकूण एकंदर | L21: =L7+L20 -> 1000 | N21: बँक | P21: =L34 -> 300 | R21: अखेरची शिल्लक | T21: =T22-T20 -> 1000
N22: हाती शिल्लक | P22: =Y29-P20-P21 -> 200 | R22: एकूण एकंदर | T22: =L21 -> 1000
N23: अखेरची शिल्लक | P23: =T21 -> 1000
M24: अक्षरी रक्कम रु. | P24: =IFERROR(IF(LEN(AC26)>11,LMT,IF(VALUE(RIGHT(INT(AC26/ABJ),2))=0,"",INDEX(MA_Num_S2G,RIGHT(INT(AC26/ABJ),2)) &ABW)&IF(VALUE(RIGHT(INT(AC26/KTI),2))=0,"",INDEX(MA_Num_S2G,RIGHT(INT(AC26/KTI),2))&KTW)&IF(VALUE(RIGHT(INT(AC26/LKS),2))=0,"",INDEX(MA_Num_S2G,RIGHT(INT(AC26/LKS),2))&LKW)&IF(VALUE(RIGHT(INT(AC26/HZR),2))=0,"",INDEX(MA_Num_S2G,RIGHT(INT(AC26/HZR),2))&HZW)&IF(RIGHT(AC26,3)="100",STK,IF(VALUE(RIGHT(INT(AC26/100),1))=0,"",INDEX(MA_Num_S2G,RIGHT(INT(AC26/100),1))&SHE))&IF(INT(RIGHT(AC26,2))=0,"",INDEX(MA_Num_S2G,RIGHT(AC26,2)))&IF(AC26=0,ZRO,"")),"") -> एक हजार
AC26: =P23 -> 1000
L28: 0 | Y28: =L21 -> 1000 | Z28: =T21 -> 1000
Y29: =P23 -> 1000
K33: DDCC बँक | L33: 500
K34: इतर बँक | L34: 300
F76: वकील जामसिंग भिल
E77: सरकार | F77: रामसिंग जामसिंग भिल
D78: 60
D79: 61
D80: 62
D81: 63
D82: 64
D83: 65
D84: 66
D85: 67
D86: 68
...

Sheet न. नं. ५ GN
A1: सामान्य कॅशबुक नमुना नं. ५
A2: ग्राम पंचायत | M2: ता. | P2: सन | S2: २०२१/२२
A3: जमा बाजू | W3: खर्च बाजू
A4: दिनांक | B4: पावती क्र. | C4: कोणाकडून मिळाले | D4: जमेचा तपशील | M4: लेखाशीर्ष | N4: जमा रक्कम | O4: सुरवातीच्या शिल्लक सहित रोजची एकूण जमा | P4: अदा केल्याची तारिख | Q4: चेक क्र. | R4: व्हौचर क्र. | S4: अदा केल्याचा तपशील | U4: लेखाशीर्ष | V4: खर्च रक्कम | W4: अखेरच्या शिल्लक सहित रोजची एकूण रु .
D5: घरपट्टी | G5: आरोग्य कर | J5: दिवाबत्ती
D6: मागील | E6: चालू | F6: एकूण | G6: मागील | H6: चालू | I6: एकूण | J6: मागील | K6: चालू | L6: एकूण | S6: कोणास अदा केले | T6: कोणत्या खात्यावर
F7: =D7+E7 -> 0 | I7: =G7+H7 -> 0 | L7: =J7+K7 -> 0 | N7: आरंभीची शिल्लक
F8: =D8+E8 -> 0 | I8: =G8+H8 -> 0 | L8: =J8+K8 -> 0 | N8: =I8+L8+F8 -> 0
F9: =D9+E9 -> 0 | I9: =G9+H9 -> 0 | L9: =J9+K9 -> 0 | N9: =I9+L9+F9 -> 0
E10: 1000 | F10: =D10+E10 -> 1000 | I10: =G10+H10 -> 0 | L10: =J10+K10 -> 0 | N10: =I10+L10+F10 -> 1000
F11: =D11+E11 -> 0 | I11: =G11+H11 -> 0 | L11: =J11+K11 -> 0 | N11: =I11+L11+F11 -> 0
F12: =D12+E12 -> 0 | I12: =G12+H12 -> 0 | L12: =J12+K12 -> 0 | N12: =I12+L12+F12 -> 0
F13: =D13+E13 -> 0 | I13: =G13+H13 -> 0 | L13: =J13+K13 -> 0 | N13: =I13+L13+F13 -> 0
F14: =D14+E14 -> 0 | I14: =G14+H14 -> 0 | L14: =J14+K14 -> 0 | N14: =I14+L14+F14 -> 0
F15: =D15+E15 -> 0 | I15: =G15+H15 -> 0 | L15: =J15+K15 -> 0 | N15: =I15+L15+F15 -> 0
F16: =D16+E16 -> 0 | I16: =G16+H16 -> 0 | L16: =J16+K16 -> 0 | N16: =I16+L16+F16 -> 0
F17: =D17+E17 -> 0 | I17: =G17+H17 -> 0 | L17: =J17+K17 -> 0 | N17: =I17+L17+F17 -> 0
F18: =D18+E18 -> 0 | I18: =G18+H18 -> 0 | L18: =J18+K18 -> 0 | N18: =I18+L18+F18 -> 0
C19: एकूण | D19: =SUM(D7:D18) -> 0 | E19: =SUM(E7:E18) -> 1000 | F19: =SUM(F7:F18) -> 1000 | G19: =SUM(G7:G18) -> 0 | H19: =SUM(H7:H18) -> 0 | I19: =SUM(I7:I18) -> 0 | J19: =SUM(J7:J18) -> 0 | K19: =SUM(K7:K18) -> 0 | L19: =SUM(L7:L18) -> 0
N20: एकूण जमा | O20: =SUM(N8:N19) -> 1000 | Q20: DDC बँकेत | S20: =O28 -> 500 | U20: आजचा खर्च | W20: =SUM(V7:V19) -> 0
N21: एकूण एकंदर | O21: =O7+O20 -> 1000 | Q21: बँक | S21: =O29 -> 300 | U21: अखेरची शिल्लक | W21: =W22-W20 -> 1000
Q22: हाती शिल्लक | S22: =AB31-S20-S21 -> 200 | U22: एकूण एकंदर | W22: =O21 -> 1000
Q23: अखेरची शिल्लक | S23: =W21 -> 1000
P24: अक्षरी रक्कम रु. | S24: =IFERROR(IF(LEN(AI27)>11,LMT,IF(VALUE(RIGHT(INT(AI27/ABJ),2))=0,"",INDEX(MA_Num_S2G,RIGHT(INT(AI27/ABJ),2)) &ABW)&IF(VALUE(RIGHT(INT(AI27/KTI),2))=0,"",INDEX(MA_Num_S2G,RIGHT(INT(AI27/KTI),2))&KTW)&IF(VALUE(RIGHT(INT(AI27/LKS),2))=0,"",INDEX(MA_Num_S2G,RIGHT(INT(AI27/LKS),2))&LKW)&IF(VALUE(RIGHT(INT(AI27/HZR),2))=0,"",INDEX(MA_Num_S2G,RIGHT(INT(AI27/HZR),2))&HZW)&IF(RIGHT(AI27,3)="100",STK,IF(VALUE(RIGHT(INT(AI27/100),1))=0,"",INDEX(MA_Num_S2G,RIGHT(INT(AI27/100),1))&SHE))&IF(INT(RIGHT(AI27,2))=0,"",INDEX(MA_Num_S2G,RIGHT(AI27,2)))&IF(AI27=0,ZRO,"")),"") -> एक हजार
AI27: =S23 -> 1000
N28: DDCC बँक | O28: 500
N29: इतर बँक | O29: 300
AB30: =O21 -> 1000 | AC30: =W21 -> 1000
AB31: =S23 -> 1000
F76: वकील जामसिंग भिल
E77: सरकार | F77: रामसिंग जामसिंग भिल
D78: 60
D79: 61
D80: 62
D81: 63
D82: 64
D83: 65
D84: 66
D85: 67
D86: 68
...

Sheet न.८ साठीचे दर
A1: बांधकाम प्रकार | B1: किमान | C1: कमाल | D1: जमिनीचे दर | E1: बांधकाम दर | F1: नवीन बांधकाम दर
A2: 1 | B2: 2 | C2: 3 | D2: 4 | E2: 5 | H2: सुचना | AM2: अंकुश आणा भिल
A3: झोपडी किंवा मातीचे घर | B3: 0.4 | C3: 0.75 | D3: 480 | E3: 6930 | F3: 6403 | H3: १ ) बांधकाम प्रकार मधील किमान दर यामध्ये सोयीनुसार दर टाकणे | AM3: अंगणवाडी
A4: दगड विटांचे मातीचे घर | B4: 0.7 | C4: 1.2 | D4: 480 | E4: 9240 | F4: 9979 | H4: २) जमिनीचे दर यामध्ये सर्व प्रकाराकरिता स्थानिक एकच दर असतो तो टाकावा | AM4: अंगणवाडी इमारत
A5: दगड विटांचे चुना किंवा सिमेंटचे पक्के घर | B5: 0.75 | C5: 1.5 | D5: 480 | E5: 13860 | F5: 14137 | H5: ३ ) बांधकामाचे दर यामध्ये स्थानिक विभाग नुसार दर टाकावे | AM5: अंगणवाडी इमारत राखीव जागा
A6: नवीन आर सी सी पद्धतीचे घर | B6: 1.2 | C6: 2 | D6: 480 | E6: 15400 | F6: 17424 | H6: ४) बखळ किंवा पडसर जागेसाठी बांधकाम दर हा ० राहू द्यावा | AM6: अंजाबाई रामा ठेलारी
A7: बखळ किंवा पडसर जागा | B7: 2.5 | C7: 5 | D7: 480 | E7: 0 | H7: ५ ) खाली घसारा दर मध्ये कोणताही बदल करू नये | AM7: अंताबाई धुडकू भिल
AM8: अंबर चंद्रा भिल
A9: Column1 | B9: Column2 | C9: Column3 | D9: Column4 | AM9: अकुबाई नारायण वंजारी
A10: ० ते २ वर्ष | B10: 1 | C10: 1 | D10: 1 | AM10: अक्षय राजेंद्र वाघ
A11: २ पेक्षा जास्त व ५ वर्ष पर्यंत | B11: 0.95 | C11: 0.95 | D11: 0.95 | AM11: अजय पंढरीनाथ माळी
A12: ५ पेक्षा जास्त व १० वर्ष पर्यंत | B12: 0.85 | C12: 0.9 | D12: 0.9 | AM12: अनिताबाई गोकुळ वंजारी
A13: १० पेक्षा जास्त व २० वर्ष पर्यंत | B13: 0.75 | C13: 0.8 | D13: 0.75 | AM13: अनिल तुकाराम देवरे
A14: २० पेक्षा जास्त व ३० वर्ष पर्यंत | B14: 0.6 | C14: 0.7 | D14: 0.6 | AM14: अभिमन हरचंद्र सोनवणे
A15: ३० पेक्षा जास्त व ४० वर्ष पर्यंत | B15: 0.45 | C15: 0.6 | D15: 0.45 | AM15: अभिषेक गोरख बिरारीस
A16: ४० पेक्षा जास्त व ५० वर्ष पर्यंत | B16: 0.3 | C16: 0.5 | D16: 0.3 | AM16: अमरधाम
A17: ५० पेक्षा जास्त व ६० वर्ष पर्यंत | B17: 0.2 | C17: 0.4 | D17: 0.2 | AM17: अमरसिंग बंधू वंजारी
A18: ६० वर्षापेक्षा जास्त | B18: 0.15 | C18: 0.3 | D18: 0.15 | AM18: अरुण ओंकार पिंपळे रंजनाबाई ऑन पिंपळे
AM19: अर्चना मनोज पाटील
AM20: अर्जुन बापू शिरसाठ जसोदाबाई अर्जुन शिरसाठ
AM21: अलकाबाई बापू पाटील
AM22: अशोक दगा पारधी
AM23: अहिल्याबाई तानाजी कन्होरे
AM24: आक्काबाई लहानू सरक
AM25: आखडू दशरथ भिल
AM26: आण्णा गणपत भिल
AM27: आण्णा भटू ठेलारी
AM28: आत्माराम भागा खांडेकर
AM29: आधार वंजी मोरे
AM30: आनंदा महादू भदाणे
... AM75: किसन रघुनाथ वाघ
F76: वकील जामसिंग भिल | AM76: केवलबाई गोपीचंद बागुल
E77: सरकार | F77: रामसिंग जामसिंग भिल | AM77: कैलास बंडू ठेलारी
D78: 60 | AM78: कोशऱ्या दशरथ भिल
D79: 61 | AM79: कौशल्याबाई पदम वंजारी
D80: 62 | AM80: कौसाबाई गटा पाटील
D81: 63 | AM81: खटाबाई लक्ष्मण हाल्लोर
D82: 64 | AM82: खिमा सोनू वंजारी
D83: 65 | AM83: गंगा दशरथ भिल
D84: 66 | AM84: गंगाबाई देविदास भिल
...

Sheet नमुना ८
A1: नमुना नंबर. ८
A2: नियम ३२ (१) | AY2: ० ते २ वर्ष | BH2: झोपडी किंवा मातीचे घर
A3: सन २०२१/२२ ते २०२४/२५ या वर्षासाठी आकारणी नोंदवही | AY3: २ पेक्षा जास्त व ५ वर्ष पर्यंत | BH3: दगड विटांचे मातीचे घर
E4: ग्रामपंचायत | F4: ='मुख्य पान '!E2 -> बळसाणे | H4: ता. | I4: ='मुख्य पान '!I2 -> साक्री | P4: जि. | Q4: ='मुख्य पान '!M2 -> धुळे | AY4: १० पेक्षा जास्त व २० वर्ष पर्यंत | BH4: नवीन आर सी सी पद्धतीचे घर
T5: =IFERROR(#REF!/1000*S10,"") | AY5: २० पेक्षा जास्त व ३० वर्ष पर्यंत | BH5: बखळ किंवा पडसर जागा
A6: अ.नं. | B6: रस्त्याचे नाव | C6: सिटी सर्व्हे नं | D6: मालमत्ता क्रमांक | E6: मालकाचे नाव. | F6: भोगवटदाराचे नाव | G6: मालमत्तेचे वर्णन | H6: मिळकत बांधकामाचे वर्ष | I6: लांबी (फुट) | J6: रुंदी (फुट) | K6: क्षेत्रफळ चौ.फुट | L6: क्षेत्रफळ चौ.मी. | M6: रेडीरेकनर दर प्रती चौ मी. (रुपये) | P6: घसारा दर | Q6: ईमारतीच्या वापरानुसार भारांक | R6: भांडवली मुल्य (रुपये) | S6: कराचा दर (पैसे) | T6: कराची रक्कम | Y6: अपिलाचे निकाल व त्यानंतर केलेले फेरफार | AD6: नंतर वाढ किवा घट झालेल्या बाबतीत आदेशाच्या संदर्भात शेरा. | AY6: ३० पेक्षा जास्त व ४० वर्ष पर्यंत
AY7: ४० पेक्षा जास्त व ५० वर्ष पर्यंत
M8: जमीन | N8: ईमारत | O8: बांधकाम | T8: घरपट्टी | U8: दिवाबत्ती | V8: आरोग्य | W8: पाणीपट्टी | X8: एकुण | Y8: घरपट्टी | Z8: दिवाबत्ती | AA8: आरोग्य | AB8: पाणीपट्टी | AC8: एकुण | AY8: ५० पेक्षा जास्त व ६० वर्ष पर्यंत
A9: 1 | B9: 2 | C9: 3 | D9: 4 | E9: 5 | G9: 7 | H9: 8 | M9: 10 | N9: 11 | O9: 12 | P9: 13 | Q9: 14 | R9: 15 | S9: 16 | T9: 17 | U9: 18 | V9: 19 | W9: 20 | X9: 21 | Y9: 22 | Z9: 23 | AA9: 24 | AB9: 25 | AC9: 26 | AD9: 27 | AY9: ६० वर्षापेक्षा जास्त
A10: 1 | D10: 1 | E10: मशिद | F10: स्वता | G10: दगड विटांचे मातीचे घर | H10: ४० पेक्षा जास्त व ५० वर्ष पर्यंत | I10: 56 | J10: 54 | L10: =K10/10.764 -> 0 | M10: =IFERROR(VLOOKUP(G10,RateB,4,TRUE),"") -> 480 | O10: =IFERROR(VLOOKUP(G10,RateB,5,TRUE),"") -> 13860 | P10: =IFERROR(VLOOKUP(H10,Demand,2,TRUE),"") -> 0.3 | Q10: 1 | R10: =IFERROR((L10*M10)+(L10*O10*P10)*Q10,"") -> 0 | S10: =IFERROR(VLOOKUP(G10,Rate,2,0),"") -> 0.7 | T10: =IFERROR(R10*S10/1000,"") -> 0 | U10: 25 | V10: 25 | W10: 360 | X10: =IFERROR(T10+U10+V10+W10,"") -> 410 | AL10: विटा, मातीचे बांधकाम, मंगलोरी कौलारु घर.
A11: 2 | D11: 2 | E11: शेख अब्दुल शेख दगू | F11: स्वतः | G11: बखळ किंवा पडसर जागा | H11: ४० पेक्षा जास्त व ५० वर्ष पर्यंत | I11: 43 | J11: 17 | K11: =I11*J11 -> 731 | L11: =K11/10.764 -> 67.911557 | M11: =IFERROR(VLOOKUP(G11,RateB,4,TRUE),"") -> 480 | O11: =IFERROR(VLOOKUP(G11,RateB,5,TRUE),"") -> 0 | P11: =IFERROR(VLOOKUP(H11,Demand,2,TRUE),"") -> 0.3 | Q11: 1 | R11: =IFERROR((L11*M11)+(L11*O11*P11)*Q11,"") -> 32597.547 | S11: =IFERROR(VLOOKUP(G11,Rate,2,0),"") -> 2.5 | T11: =IFERROR(R11*S11/1000,"") -> 81.493868 | U11: 10 | V11: 10 | W11: 0 | X11: =IFERROR(T11+U11+V11+W11,"") -> 101.49387 | AL11: विटा, मातीचे बांधकाम, मंगलोरी कौलारु घर.
A12: 3 | D12: 3 | E12: तुकाराम महादू मासुळे | F12: स्वतः | G12: दगड विटांचे मातीचे घर | H12: ५० पेक्षा जास्त व ६० वर्ष पर्यंत | I12: 43 | J12: 15 | K12: =I12*J12 -> 645 | L12: =K12/10.764 -> 59.921962 | M12: =IFERROR(VLOOKUP(G12,RateB,4,TRUE),"") -> 480 | O12: =IFERROR(VLOOKUP(G12,RateB,5,TRUE),"") -> 13860 | P12: =IFERROR(VLOOKUP(H12,Demand,2,TRUE),"") -> 0.2 | Q12: 1 | R12: =IFERROR((L12*M12)+(L12*O12*P12)*Q12,"") -> 194866.22 | S12: =IFERROR(VLOOKUP(G12,Rate,2,0),"") -> 0.7 | T12: =IFERROR(R12*S12/1000,"") -> 136.40635 | U12: 0 | V12: 0 | W12: 0 | X12: =IFERROR(T12+U12+V12+W12,"") -> 136.40635 | AL12: विटा,सिमेंट,वाळुचे बंधकाम सिमेंट पत्र्याचे सौचालयासह पक्के घर
A13: 4 | D13: 4 | E13: शे.शामसादिक अहमद | F13: स्वतः | G13: झोपडी किंवा मातीचे घर | H13: ५० पेक्षा जास्त व ६० वर्ष पर्यंत | I13: 43 | J13: 16 | K13: =I13*J13 -> 688 | L13: =K13/10.764 -> 63.91676 | M13: =IFERROR(VLOOKUP(G13,RateB,4,TRUE),"") -> 480 | O13: =IFERROR(VLOOKUP(G13,RateB,5,TRUE),"") -> 6930 | P13: =IFERROR(VLOOKUP(H13,Demand,2,TRUE),"") -> 0.2 | Q13: 1 | R13: =IFERROR((L13*M13)+(L13*O13*P13)*Q13,"") -> 119268.67 | S13: =IFERROR(VLOOKUP(G13,Rate,2,0),"") -> 0.4 | T13: =IFERROR(R13*S13/1000,"") -> 47.707469 | U13: 25 | V13: 25 | W13: 360 | X13: =IFERROR(T13+U13+V13+W13,"") -> 457.70747 | AL13: विटा, मातीचे बांधकाम, कौलारु घर.
K14: =I14*J14 -> 0 | L14: =K14/10.764 -> 0 | M14: =IFERROR(VLOOKUP(G14,RateB,4,TRUE),"") | O14: =IFERROR(VLOOKUP(G14,RateB,5,TRUE),"") | P14: =IFERROR(VLOOKUP(H14,Demand,2,TRUE),"") | Q14: 1 | R14: =IFERROR((L14*M14)+(L14*O14*P14)*Q14,"") | S14: =IFERROR(VLOOKUP(G14,Rate,2,0),"") | T14: =IFERROR(R14*S14/1000,"") | U14: 25 | V14: 25 | W14: 360 | X14: =IFERROR(T14+U14+V14+W14,"") | AL14: बखळ किंवा पडसर जागा
A15: 5 | D15: 5 | E15: लक्ष्मन तुकाराम मासुळे | F15: स्वतः | G15: बखळ किंवा पडसर जागा | H15: ५० पेक्षा जास्त व ६० वर्ष पर्यंत | I15: 43 | J15: 8 | K15: =I15*J15 -> 344 | L15: =K15/10.764 -> 31.95838 | M15: =IFERROR(VLOOKUP(G15,RateB,4,TRUE),"") -> 480 | O15: =IFERROR(VLOOKUP(G15,RateB,5,TRUE),"") -> 0 | P15: =IFERROR(VLOOKUP(H15,Demand,2,TRUE),"") -> 0.2 | Q15: 1 | R15: =IFERROR((L15*M15)+(L15*O15*P15)*Q15,"") -> 15340.022 | T15: =IFERROR(R15*S15/1000,"") | U15: 0 | V15: 0 | W15: 0 | X15: =IFERROR(T15+U15+V15+W15,"")
A16: 6 | D16: 5 | E16: वना श्रीराम पद्मोर | F16: स्वतः | G16: बखळ किंवा पडसर जागा | I16: 43 | J16: 8 | K16: =I16*J16 -> 344 | L16: =K16/10.764 -> 31.95838 | M16: =IFERROR(VLOOKUP(G16,RateB,4,TRUE),"") -> 480 | O16: =IFERROR(VLOOKUP(G16,RateB,5,TRUE),"") -> 0 | P16: =IFERROR(VLOOKUP(H16,Demand,2,TRUE),"") | Q16: 1 | R16: =IFERROR((L16*M16)+(L16*O16*P16)*Q16,"") | S16: =IFERROR(VLOOKUP(G16,Rate,2,0),"") -> 2.5 | T16: =IFERROR(R16*S16/1000,"") | U16: 25 | V16: 25 | W16: 360 | X16: =IFERROR(T16+U16+V16+W16,T16)
A17: 7 | D17: 6 | E17: अर्स्तोलबाई शानाभाऊ मासुळे | F17: स्वतः | G17: झोपडी किंवा मातीचे घर | H17: ५० पेक्षा जास्त व ६० वर्ष पर्यंत | I17: 43 | J17: 15 | K17: =I17*J17 -> 645 | L17: =K17/10.764 -> 59.921962 | M17: =IFERROR(VLOOKUP(G17,RateB,4,TRUE),"") -> 480 | O17: =IFERROR(VLOOKUP(G17,RateB,5,TRUE),"") -> 6930 | P17: =IFERROR(VLOOKUP(H17,Demand,2,TRUE),"") -> 0.2 | Q17: 1 | R17: =IFERROR((L17*M17)+(L17*O17*P17)*Q17,"") -> 111814.38 | S17: =IFERROR(VLOOKUP(G17,Rate,2,0),"") -> 0.4 | T17: =IFERROR(R17*S17/1000,"") -> 44.725753 | U17: 25 | V17: 25 | W17: 360 | X17: =IFERROR(T17+U17+V17+W17,"") -> 454.72575
A18: 8 | D18: 7 | E18: शानाभाऊ लाला मासुळे | F18: स्वतः | G18: झोपडी किंवा मातीचे घर | H18: ५० पेक्षा जास्त व ६० वर्ष पर्यंत | I18: 43 | J18: 7 | K18: =I18*J18 -> 301 | L18: =K18/10.764 -> 27.963582 | M18: =IFERROR(VLOOKUP(G18,RateB,4,TRUE),"") -> 480 | O18: =IFERROR(VLOOKUP(G18,RateB,5,TRUE),"") -> 6930 | P18: =IFERROR(VLOOKUP(H18,Demand,2,TRUE),"") -> 0.2 | Q18: 1 | R18: =IFERROR((L18*M18)+(L18*O18*P18)*Q18,"") -> 52180.045 | S18: =IFERROR(VLOOKUP(G18,Rate,2,0),"") -> 0.4 | T18: =IFERROR(R18*S18/1000,"") -> 20.872018 | U18: 25 | V18: 25 | W18: 360 | X18: =IFERROR(T18+U18+V18+W18,"") -> 430.87202
A19: 9 | D19: 8 | E19: रत्नाबाई बापू पाटील | F19: स्वतः | G19: दगड विटांचे मातीचे घर | H19: ५० पेक्षा जास्त व ६० वर्ष पर्यंत | K19: =I19*J19 -> 0 | L19: =K19/10.764 -> 0 | M19: =IFERROR(VLOOKUP(G19,RateB,4,TRUE),"") -> 480 | O19: =IFERROR(VLOOKUP(G19,RateB,5,TRUE),"") -> 13860 | P19: =IFERROR(VLOOKUP(H19,Demand,2,TRUE),"") -> 0.2 | Q19: 1 | R19: =IFERROR((L19*M19)+(L19*O19*P19)*Q19,"") -> 0 | S19: =IFERROR(VLOOKUP(G19,Rate,2,0),"") -> 0.7 | T19: =IFERROR(R19*S19/1000,"") -> 0 | U19: 25 | V19: 25 | W19: 360 | X19: =IFERROR(T19+U19+V19+W19,"") -> 410
A20: 10 | D20: 9 | E20: बापू नथा पाटील | F20: स्वतः | G20: झोपडी किंवा मातीचे घर | H20: ५० पेक्षा जास्त व ६० वर्ष पर्यंत | I20: 43 | J20: 7 | K20: =I20*J20 -> 301 | L20: =K20/10.764 -> 27.963582 | M20: =IFERROR(VLOOKUP(G20,RateB,4,TRUE),"") -> 480 | O20: =IFERROR(VLOOKUP(G20,RateB,5,TRUE),"") -> 6930 | P20: =IFERROR(VLOOKUP(H20,Demand,2,TRUE),"") -> 0.2 | Q20: 1 | R20: =IFERROR((L20*M20)+(L20*O20*P20)*Q20,"") -> 52180.045 | S20: =IFERROR(VLOOKUP(G20,Rate,2,0),"") -> 0.4 | T20: =IFERROR(R20*S20/1000,"") -> 20.872018 | U20: 25 | V20: 25 | W20: 360 | X20: =IFERROR(T20+U20+V20+W20,"") -> 430.87202
A21: 11 | D21: 10 | E21: रमणबाई धनराज मासुळे | F21: स्वतः | G21: झोपडी किंवा मातीचे घर | H21: ५० पेक्षा जास्त व ६० वर्ष पर्यंत | I21: 43 | J21: 7 | K21: =I21*J21 -> 301 | L21: =K21/10.764 -> 27.963582 | M21: =IFERROR(VLOOKUP(G21,RateB,4,TRUE),"") -> 480 | O21: =IFERROR(VLOOKUP(G21,RateB,5,TRUE),"") -> 6930 | P21: =IFERROR(VLOOKUP(H21,Demand,2,TRUE),"") -> 0.2 | Q21: 1 | R21: =IFERROR((L21*M21)+(L21*O21*P21)*Q21,"") -> 52180.045 | S21: =IFERROR(VLOOKUP(G21,Rate,2,0),"") -> 0.4 | T21: =IFERROR(R21*S21/1000,"") -> 20.872018 | U21: 25 | V21: 25 | W21: 360 | X21: =IFERROR(T21+U21+V21+W21,"") -> 430.87202
A22: 12 | D22: 11 | E22: योगेश भगवान पाटील | F22: स्वतः | G22: झोपडी किंवा मातीचे घर | H22: ५० पेक्षा जास्त व ६० वर्ष पर्यंत | I22: 49 | J22: 16 | K22: =I22*J22 -> 784 | L22: =K22/10.764 -> 72.835377 | M22: =IFERROR(VLOOKUP(G22,RateB,4,TRUE),"") -> 480 | O22: =IFERROR(VLOOKUP(G22,RateB,5,TRUE),"") -> 6930 | P22: =IFERROR(VLOOKUP(H22,Demand,2,TRUE),"") -> 0.2 | Q22: 1 | R22: =IFERROR((L22*M22)+(L22*O22*P22)*Q22,"") -> 135910.81 | S22: =IFERROR(VLOOKUP(G22,Rate,2,0),"") -> 0.4 | T22: =IFERROR(R22*S22/1000,"") -> 54.364326 | U22: 25 | V22: 25 | W22: 360 | X22: =IFERROR(T22+U22+V22+W22,"") -> 464.36433
A23: 13 | D23: 12 | E23: शे.अब्दुल शे. काळू | F23: स्वतः | G23: झोपडी किंवा मातीचे घर | H23: ५० पेक्षा जास्त व ६० वर्ष पर्यंत | I23: 49 | J23: 16 | K23: =I23*J23 -> 784 | L23: =K23/10.764 -> 72.835377 | M23: =IFERROR(VLOOKUP(G23,RateB,4,TRUE),"") -> 480 | O23: =IFERROR(VLOOKUP(G23,RateB,5,TRUE),"") -> 6930 | P23: =IFERROR(VLOOKUP(H23,Demand,2,TRUE),"") -> 0.2 | Q23: 1 | R23: =IFERROR((L23*M23)+(L23*O23*P23)*Q23,"") -> 135910.81 | S23: =IFERROR(VLOOKUP(G23,Rate,2,0),"") -> 0.4 | T23: =IFERROR(R23*S23/1000,"") -> 54.364326 | U23: 25 | V23: 25 | W23: 360 | X23: =IFERROR(T23+U23+V23+W23,"") -> 464.36433
A24: 14 | D24: 13 | E24: शे.करीम शे. काळू | F24: स्वतः | G24: झोपडी किंवा मातीचे घर | H24: ५० पेक्षा जास्त व ६० वर्ष पर्यंत | I24: 49 | J24: 14 | K24: =I24*J24 -> 686 | L24: =K24/10.764 -> 63.730955 | M24: =IFERROR(VLOOKUP(G24,RateB,4,TRUE),"") -> 480 | O24: =IFERROR(VLOOKUP(G24,RateB,5,TRUE),"") -> 6930 | P24: =IFERROR(VLOOKUP(H24,Demand,2,TRUE),"") -> 0.2 | Q24: 1 | R24: =IFERROR((L24*M24)+(L24*O24*P24)*Q24,"") -> 118921.96 | S24: =IFERROR(VLOOKUP(G24,Rate,2,0),"") -> 0.4 | T24: =IFERROR(R24*S24/1000,"") -> 47.568785 | U24: 25 | V24: 25 | W24: 360 | X24: =IFERROR(T24+U24+V24+W24,"") -> 457.56878
A25: 15 | D25: 14 | E25: सखुबाई बाप अर्जुन पाटील | F25: स्वतः | G25: झोपडी किंवा मातीचे घर | H25: ४० पेक्षा जास्त व ५० वर्ष पर्यंत | I25: 49 | J25: 14 | K25: =I25*J25 -> 686 | L25: =K25/10.764 -> 63.730955 | M25: =IFERROR(VLOOKUP(G25,RateB,4,TRUE),"") -> 480 | O25: =IFERROR(VLOOKUP(G25,RateB,5,TRUE),"") -> 6930 | P25: =IFERROR(VLOOKUP(H25,Demand,2,TRUE),"") -> 0.3 | Q25: 1 | R25: =IFERROR((L25*M25)+(L25*O25*P25)*Q25,"") -> 163087.51 | S25: =IFERROR(VLOOKUP(G25,Rate,2,0),"") -> 0.4 | T25: =IFERROR(R25*S25/1000,"") -> 65.235006 | U25: 25 | V25: 25 | W25: 360 | X25: =IFERROR(T25+U25+V25+W25,"") -> 475.23501
A26: 16 | D26: 15 | E26: सरकार | F26: बापू नथा पाटील | G26: झोपडी किंवा मातीचे घर | H26: ४० पेक्षा जास्त व ५० वर्ष पर्यंत | I26: 49 | J26: 16 | K26: =I26*J26 -> 784 | L26: =K26/10.764 -> 72.835377 | M26: =IFERROR(VLOOKUP(G26,RateB,4,TRUE),"") -> 480 | O26: =IFERROR(VLOOKUP(G26,RateB,5,TRUE),"") -> 6930 | P26: =IFERROR(VLOOKUP(H26,Demand,2,TRUE),"") -> 0.3 | Q26: 1 | R26: =IFERROR((L26*M26)+(L26*O26*P26)*Q26,"") -> 186385.73 | S26: =IFERROR(VLOOKUP(G26,Rate,2,0),"") -> 0.4 | T26: =IFERROR(R26*S26/1000,"") -> 74.554292 | U26: 25 | V26: 25 | W26: 360 | X26: =IFERROR(T26+U26+V26+W26,"") -> 484.55429
A27: 17 | D27: 16 | E27: सरकार | F27: भगवान सोमा | G27: दगड विटांचे मातीचे घर | H27: १० पेक्षा जास्त व २० वर्ष पर्यंत | I27: 49 | J27: 9 | K27: =I27*J27 -> 441 | L27: =K27/10.764 -> 40.9699 | M27: =IFERROR(VLOOKUP(G27,RateB,4,TRUE),"") -> 480 | O27: =IFERROR(VLOOKUP(G27,RateB,5,TRUE),"") -> 13860 | P27: =IFERROR(VLOOKUP(H27,Demand,2,TRUE),"") -> 1 | Q27: 1 | R27: =IFERROR((L27*M27)+(L27*O27*P27)*Q27,"") -> 587508.36 | S27: =IFERROR(VLOOKUP(G27,Rate,2,0),"") -> 0.7 | T27: =IFERROR(R27*S27/1000,"") -> 411.25585 | U27: 25 | V27: 25 | W27: 360 | X27: =IFERROR(T27+U27+V27+W27,"") -> 821.25585
A28: 18 | D28: 17 | E28: सरकार | F28: बोळ | K28: =I28*J28 -> 0 | L28: =K28/10.764 -> 0 | M28: =IFERROR(VLOOKUP(G28,RateB,4,TRUE),"") | O28: =IFERROR(VLOOKUP(G28,RateB,5,TRUE),"") | P28: =IFERROR(VLOOKUP(H28,Demand,2,TRUE),"") | Q28: 1 | R28: =IFERROR((L28*M28)+(L28*O28*P28)*Q28,"") | S28: =IFERROR(VLOOKUP(G28,Rate,2,0),"") | T28: =IFERROR(R28*S28/1000,"") | U28: 25 | V28: 25 | W28: 360 | X28: =IFERROR(T28+U28+V28+W28,"")
A29: 19 | D29: १८ | E29: लताबाई हिलाल राजपूत | F29: सरकार | G29: नवीन आर सी सी पद्धतीचे घर | H29: १० पेक्षा जास्त व २० वर्ष पर्यंत | I29: 49 | J29: 13 | K29: =I29*J29 -> 637 | L29: =K29/10.764 -> 59.178744 | M29: =IFERROR(VLOOKUP(G29,RateB,4,TRUE),"") -> 480 | O29: =IFERROR(VLOOKUP(G29,RateB,5,TRUE),"") -> 15400 | P29: =IFERROR(VLOOKUP(H29,Demand,2,TRUE),"") -> 1 | Q29: 1 | R29: =IFERROR((L29*M29)+(L29*O29*P29)*Q29,"") -> 939758.45 | S29: =IFERROR(VLOOKUP(G29,Rate,2,0),"") -> 1.2 | T29: =IFERROR(R29*S29/1000,"") -> 1127.7101 | U29: 25 | V29: 25 | W29: 360 | X29: =IFERROR(T29+U29+V29+W29,"") -> 1537.7101
D30: १८ | E30: सरकार | F30: लताबाई हिलाल राजपूत | G30: नवीन आर सी सी पद्धतीचे घर | H30: २० पेक्षा जास्त व ३० वर्ष पर्यंत | I30: 49 | J30: 13 | K30: =I30*J30 -> 637 | L30: =K30/10.764 -> 59.178744
